Workbook

Sheet Smart Dashboard
A1: ⌂ | C1: STATUS GODOWN NO. 9, 14, 18 AND 20 | M1: ="LAST UPDATED | "&TEXT(NOW(),"dd.mm.yy")&" | "&TEXT(NOW(),"HH:mm") | Q1: Stack Type | R1: Count | S1: Status | T1: Count | U1: Infested Rank | V1: Due Rank
Q2: Wheat | R2: =B11 | S2: Clear | T2: =G11 | U2: =IF(AND('Master Stock'!D2<>"",'Master Stock'!H2="OCCUPIED",'Master Stock'!J2<>"",'Master Stock'!K2=""),COUNT($U$1:U1)+1,"") | V2: =IF(AND('Master Stock'!D2<>"",'Master Stock'!L2<>"",'Master Stock'!L2<TODAY()-30),COUNT($V$1:V1)+1,"")
A3: TOTAL STACK | C3: FULL STACK | E3: EMPTY STACK | G3: INFESTED / UNDER COVER | I3: FUMIGATION DUE | K3: QUICK NAVIGATION | Q3: Rice (FRK + RRA) | R3: =B12 | S3: Infested / Under Cover | T3: =G12 | U3: =IF(AND('Master Stock'!D3<>"",'Master Stock'!H3="OCCUPIED",'Master Stock'!J3<>"",'Master Stock'!K3=""),COUNT($U$1:U2)+1,"") | V3: =IF(AND('Master Stock'!D3<>"",'Master Stock'!L3<>"",'Master Stock'!L3<TODAY()-30),COUNT($V$1:V2)+1,"")
A4: =COUNTIF('Master Stock'!$D$2:$D$1000,"<>") | C4: =COUNTIFS('Master Stock'!$D$2:$D$1000,"<>",'Master Stock'!$H$2:$H$1000,"OCCUPIED") | E4: =COUNTIFS('Master Stock'!$D$2:$D$1000,"<>",'Master Stock'!$H$2:$H$1000,"EMPTY") | G4: =COUNTIFS('Master Stock'!$D$2:$D$1000,"<>",'Master Stock'!$H$2:$H$1000,"OCCUPIED",'Master Stock'!$J$2:$J$1000,"<>",'Master Stock'!$K$2:$K$1000,"") | I4: =COUNTIFS('Master Stock'!$D$2:$D$1000,"<>",'Master Stock'!$L$2:$L$1000,"<>" ,'Master Stock'!$L$2:$L$1000,"<"&TODAY()-30) | K4: ☷ QC DETAILS | Q4: Empty Stack | R4: =B13 | S4: Fumigation Due | T4: =G13 | U4: =IF(AND('Master Stock'!D4<>"",'Master Stock'!H4="OCCUPIED",'Master Stock'!J4<>"",'Master Stock'!K4=""),COUNT($U$1:U3)+1,"") | V4: =IF(AND('Master Stock'!D4<>"",'Master Stock'!L4<>"",'Master Stock'!L4<TODAY()-30),COUNT($V$1:V3)+1,"")
U5: =IF(AND('Master Stock'!D5<>"",'Master Stock'!H5="OCCUPIED",'Master Stock'!J5<>"",'Master Stock'!K5=""),COUNT($U$1:U4)+1,"") | V5: =IF(AND('Master Stock'!D5<>"",'Master Stock'!L5<>"",'Master Stock'!L5<TODAY()-30),COUNT($V$1:V4)+1,"")
K6: ▤ MASTER | U6: =IF(AND('Master Stock'!D6<>"",'Master Stock'!H6="OCCUPIED",'Master Stock'!J6<>"",'Master Stock'!K6=""),COUNT($U$1:U5)+1,"") | V6: =IF(AND('Master Stock'!D6<>"",'Master Stock'!L6<>"",'Master Stock'!L6<TODAY()-30),COUNT($V$1:V5)+1,"")
A7: All Stacks | C7: Full Stacks | E7: Empty Stacks | G7: Requires Attention | I7: Due for Fumigation | U7: =IF(AND('Master Stock'!D7<>"",'Master Stock'!H7="OCCUPIED",'Master Stock'!J7<>"",'Master Stock'!K7=""),COUNT($U$1:U6)+1,"") | V7: =IF(AND('Master Stock'!D7<>"",'Master Stock'!L7<>"",'Master Stock'!L7<TODAY()-30),COUNT($V$1:V6)+1,"")
K8: 🌾 RICE PRIORITY | U8: =IF(AND('Master Stock'!D8<>"",'Master Stock'!H8="OCCUPIED",'Master Stock'!J8<>"",'Master Stock'!K8=""),COUNT($U$1:U7)+1,"") | V8: =IF(AND('Master Stock'!D8<>"",'Master Stock'!L8<>"",'Master Stock'!L8<TODAY()-30),COUNT($V$1:V7)+1,"")
A9: STACK TYPE SUMMARY | C9: STACK MIX | F9: INFESTATION STATUS | H9: INFESTATION STATUS | U9: =IF(AND('Master Stock'!D9<>"",'Master Stock'!H9="OCCUPIED",'Master Stock'!J9<>"",'Master Stock'!K9=""),COUNT($U$1:U8)+1,"") | V9: =IF(AND('Master Stock'!D9<>"",'Master Stock'!L9<>"",'Master Stock'!L9<TODAY()-30),COUNT($V$1:V8)+1,"")
A10: STACK TYPE | B10: COUNT | F10: STATUS | G10: COUNT | K10: 🌾 WHEAT PRIORITY | U10: =IF(AND('Master Stock'!D10<>"",'Master Stock'!H10="OCCUPIED",'Master Stock'!J10<>"",'Master Stock'!K10=""),COUNT($U$1:U9)+1,"") | V10: =IF(AND('Master Stock'!D10<>"",'Master Stock'!L10<>"",'Master Stock'!L10<TODAY()-30),COUNT($V$1:V9)+1,"")
A11: Wheat | B11: =COUNTIFS('Master Stock'!$D$2:$D$1000,"<>",'Master Stock'!$G$2:$G$1000,"*WHEAT*") | F11: Clear | G11: =MAX(0,$C$4-$G$4) | U11: =IF(AND('Master Stock'!D11<>"",'Master Stock'!H11="OCCUPIED",'Master Stock'!J11<>"",'Master Stock'!K11=""),COUNT($U$1:U10)+1,"") | V11: =IF(AND('Master Stock'!D11<>"",'Master Stock'!L11<>"",'Master Stock'!L11<TODAY()-30),COUNT($V$1:V10)+1,"")
A12: Rice (FRK + RRA) | B12: =COUNTIFS('Master Stock'!$D$2:$D$1000,"<>",'Master Stock'!$G$2:$G$1000,"*FRK*",'Master Stock'!$G$2:$G$1000,"*RRA*") | F12: Infested / Under Cover | G12: =$G$4 | U12: =IF(AND('Master Stock'!D12<>"",'Master Stock'!H12="OCCUPIED",'Master Stock'!J12<>"",'Master Stock'!K12=""),COUNT($U$1:U11)+1,"") | V12: =IF(AND('Master Stock'!D12<>"",'Master Stock'!L12<>"",'Master Stock'!L12<TODAY()-30),COUNT($V$1:V11)+1,"")
A13: Empty Stack | B13: =COUNTIFS('Master Stock'!$D$2:$D$1000,"<>",'Master Stock'!$H$2:$H$1000,"EMPTY") | F13: Fumigation Due | G13: =$I$4 | K13: SEARCH STACK | U13: =IF(AND('Master Stock'!D13<>"",'Master Stock'!H13="OCCUPIED",'Master Stock'!J13<>"",'Master Stock'!K13=""),COUNT($U$1:U12)+1,"") | V13: =IF(AND('Master Stock'!D13<>"",'Master Stock'!L13<>"",'Master Stock'!L13<TODAY()-30),COUNT($V$1:V12)+1,"")
A14: TOTAL | B14: =SUM(B11:B13) | K14: 9A05 | U14: =IF(AND('Master Stock'!D14<>"",'Master Stock'!H14="OCCUPIED",'Master Stock'!J14<>"",'Master Stock'!K14=""),COUNT($U$1:U13)+1,"") | V14: =IF(AND('Master Stock'!D14<>"",'Master Stock'!L14<>"",'Master Stock'!L14<TODAY()-30),COUNT($V$1:V13)+1,"")
U15: =IF(AND('Master Stock'!D15<>"",'Master Stock'!H15="OCCUPIED",'Master Stock'!J15<>"",'Master Stock'!K15=""),COUNT($U$1:U14)+1,"") | V15: =IF(AND('Master Stock'!D15<>"",'Master Stock'!L15<>"",'Master Stock'!L15<TODAY()-30),COUNT($V$1:V14)+1,"")
U16: =IF(AND('Master Stock'!D16<>"",'Master Stock'!H16="OCCUPIED",'Master Stock'!J16<>"",'Master Stock'!K16=""),COUNT($U$1:U15)+1,"") | V16: =IF(AND('Master Stock'!D16<>"",'Master Stock'!L16<>"",'Master Stock'!L16<TODAY()-30),COUNT($V$1:V15)+1,"")
K17: Stack No. | L17: {=IF($K$14="","",IFERROR(INDEX('Master Stock'!$D$2:$D$1000,MATCH($K$14,'Master Stock'!$D$2:$D$1000,0)),""))} | U17: =IF(AND('Master Stock'!D17<>"",'Master Stock'!H17="OCCUPIED",'Master Stock'!J17<>"",'Master Stock'!K17=""),COUNT($U$1:U16)+1,"") | V17: =IF(AND('Master Stock'!D17<>"",'Master Stock'!L17<>"",'Master Stock'!L17<TODAY()-30),COUNT($V$1:V16)+1,"")
K18: Commodity | L18: {=IF($K$14="","",IFERROR(INDEX('Master Stock'!$G$2:$G$1000,MATCH($K$14,'Master Stock'!$D$2:$D$1000,0)),""))} | U18: =IF(AND('Master Stock'!D18<>"",'Master Stock'!H18="OCCUPIED",'Master Stock'!J18<>"",'Master Stock'!K18=""),COUNT($U$1:U17)+1,"") | V18: =IF(AND('Master Stock'!D18<>"",'Master Stock'!L18<>"",'Master Stock'!L18<TODAY()-30),COUNT($V$1:V17)+1,"")
K19: Date of Receipt | L19: {=IF($K$14="","",IFERROR(INDEX('Master Stock'!$B$2:$B$1000,MATCH($K$14,'Master Stock'!$D$2:$D$1000,0)),""))} | U19: =IF(AND('Master Stock'!D19<>"",'Master Stock'!H19="OCCUPIED",'Master Stock'!J19<>"",'Master Stock'!K19=""),COUNT($U$1:U18)+1,"") | V19: =IF(AND('Master Stock'!D19<>"",'Master Stock'!L19<>"",'Master Stock'!L19<TODAY()-30),COUNT($V$1:V18)+1,"")
A20: 🐞 INFESTED / UNDER COVER DETAILS | E20: 🧯 FUMIGATION DUE DETAILS | K20: Last Fumigation | L20: {=IF($K$14="","",IFERROR(INDEX('Master Stock'!$L$2:$L$1000,MATCH($K$14,'Master Stock'!$D$2:$D$1000,0)),""))} | U20: =IF(AND('Master Stock'!D20<>"",'Master Stock'!H20="OCCUPIED",'Master Stock'!J20<>"",'Master Stock'!K20=""),COUNT($U$1:U19)+1,"") | V20: =IF(AND('Master Stock'!D20<>"",'Master Stock'!L20<>"",'Master Stock'!L20<TODAY()-30),COUNT($V$1:V19)+1,"")
A21: Stack No. | B21: Commodity | C21: Fumigation Date | D21: Days | E21: Stack No. | F21: Commodity | G21: Last Fumigation | H21: Days | I21: Status | K21: Fumigation Days | L21: =IF(L20="","",MAX(0,TODAY()-L20)) | U21: =IF(AND('Master Stock'!D21<>"",'Master Stock'!H21="OCCUPIED",'Master Stock'!J21<>"",'Master Stock'!K21=""),COUNT($U$1:U20)+1,"") | V21: =IF(AND('Master Stock'!D21<>"",'Master Stock'!L21<>"",'Master Stock'!L21<TODAY()-30),COUNT($V$1:V20)+1,"")
A22: {=IFERROR(INDEX('Master Stock'!$D$2:$D$1000,MATCH(1,$U$2:$U$1000,0)),"")} | B22: {=IFERROR(INDEX('Master Stock'!$G$2:$G$1000,MATCH(1,$U$2:$U$1000,0)),"")} | C22: {=IFERROR(INDEX('Master Stock'!$J$2:$J$1000,MATCH(1,$U$2:$U$1000,0)),"")} | D22: =IF(C22="","",MAX(0,TODAY()-C22)) | E22: {=IFERROR(INDEX('Master Stock'!$D$2:$D$1000,MATCH(1,$V$2:$V$1000,0)),"")} | F22: {=IFERROR(INDEX('Master Stock'!$G$2:$G$1000,MATCH(1,$V$2:$V$1000,0)),"")} | G22: {=IFERROR(INDEX('Master Stock'!$L$2:$L$1000,MATCH(1,$V$2:$V$1000,0)),"")} | H22: =IF(G22="","",MAX(0,TODAY()-G22)) | I22: =IF(E22="","","DUE (30+ Days)") | K22: Status | L22: {=IF(L17="","",IF(AND(INDEX('Master Stock'!$J$2:$J$1000,MATCH($K$14,'Master Stock'!$D$2:$D$1000,0))<>"",INDEX('Master Stock'!$K$2:$K$1000,MATCH($K$14,'Master Stock'!$D$2:$D$1000,0))=""),"INFESTED / UNDER COVER",IF(AND(L20<>"",L21>30),"FUMIGATION DUE","CLEAR")))} | U22: =IF(AND('Master Stock'!D22<>"",'Master Stock'!H22="OCCUPIED",'Master Stock'!J22<>"",'Master Stock'!K22=""),COUNT($U$1:U21)+1,"") | V22: =IF(AND('Master Stock'!D22<>"",'Master Stock'!L22<>"",'Master Stock'!L22<TODAY()-30),COUNT($V$1:V21)+1,"")
A23: {=IFERROR(INDEX('Master Stock'!$D$2:$D$1000,MATCH(2,$U$2:$U$1000,0)),"")} | B23: {=IFERROR(INDEX('Master Stock'!$G$2:$G$1000,MATCH(2,$U$2:$U$1000,0)),"")} | C23: {=IFERROR(INDEX('Master Stock'!$J$2:$J$1000,MATCH(2,$U$2:$U$1000,0)),"")} | D23: =IF(C23="","",MAX(0,TODAY()-C23)) | E23: {=IFERROR(INDEX('Master Stock'!$D$2:$D$1000,MATCH(2,$V$2:$V$1000,0)),"")} | F23: {=IFERROR(INDEX('Master Stock'!$G$2:$G$1000,MATCH(2,$V$2:$V$1000,0)),"")} | G23: {=IFERROR(INDEX('Master Stock'!$L$2:$L$1000,MATCH(2,$V$2:$V$1000,0)),"")} | H23: =IF(G23="","",MAX(0,TODAY()-G23)) | I23: =IF(E23="","","DUE (30+ Days)") | L23: {=IF($K$14="","",IF(L17="","",IF(AND(L20<>"",L21>30),"FUMIGATION DUE",IF(AND(INDEX('Master Stock'!$J$2:$J$1000,MATCH($K$14,'Master Stock'!$D$2:$D$1000,0))<>"",INDEX('Master Stock'!$K$2:$K$1000,MATCH($K$14,'Master Stock'!$D$2:$D$1000,0))=""),"INFESTED / UNDER COVER","CLEAR"))))} | U23: =IF(AND('Master Stock'!D23<>"",'Master Stock'!H23="OCCUPIED",'Master Stock'!J23<>"",'Master Stock'!K23=""),COUNT($U$1:U22)+1,"") | V23: =IF(AND('Master Stock'!D23<>"",'Master Stock'!L23<>"",'Master Stock'!L23<TODAY()-30),COUNT($V$1:V22)+1,"")
A24: {=IFERROR(INDEX('Master Stock'!$D$2:$D$1000,MATCH(3,$U$2:$U$1000,0)),"")} | B24: {=IFERROR(INDEX('Master Stock'!$G$2:$G$1000,MATCH(3,$U$2:$U$1000,0)),"")} | C24: {=IFERROR(INDEX('Master Stock'!$J$2:$J$1000,MATCH(3,$U$2:$U$1000,0)),"")} | D24: =IF(C24="","",MAX(0,TODAY()-C24)) | E24: {=IFERROR(INDEX('Master Stock'!$D$2:$D$1000,MATCH(3,$V$2:$V$1000,0)),"")} | F24: {=IFERROR(INDEX('Master Stock'!$G$2:$G$1000,MATCH(3,$V$2:$V$1000,0)),"")} | G24: {=IFERROR(INDEX('Master Stock'!$L$2:$L$1000,MATCH(3,$V$2:$V$1000,0)),"")} | H24: =IF(G24="","",MAX(0,TODAY()-G24)) | I24: =IF(E24="","","DUE (30+ Days)") | U24: =IF(AND('Master Stock'!D24<>"",'Master Stock'!H24="OCCUPIED",'Master Stock'!J24<>"",'Master Stock'!K24=""),COUNT($U$1:U23)+1,"") | V24: =IF(AND('Master Stock'!D24<>"",'Master Stock'!L24<>"",'Master Stock'!L24<TODAY()-30),COUNT($V$1:V23)+1,"")
A25: {=IFERROR(INDEX('Master Stock'!$D$2:$D$1000,MATCH(4,$U$2:$U$1000,0)),"")} | B25: {=IFERROR(INDEX('Master Stock'!$G$2:$G$1000,MATCH(4,$U$2:$U$1000,0)),"")} | C25: {=IFERROR(INDEX('Master Stock'!$J$2:$J$1000,MATCH(4,$U$2:$U$1000,0)),"")} | D25: =IF(C25="","",MAX(0,TODAY()-C25)) | E25: {=IFERROR(INDEX('Master Stock'!$D$2:$D$1000,MATCH(4,$V$2:$V$1000,0)),"")} | F25: {=IFERROR(INDEX('Master Stock'!$G$2:$G$1000,MATCH(4,$V$2:$V$1000,0)),"")} | G25: {=IFERROR(INDEX('Master Stock'!$L$2:$L$1000,MATCH(4,$V$2:$V$1000,0)),"")} | H25: =IF(G25="","",MAX(0,TODAY()-G25)) | I25: =IF(E25="","","DUE (30+ Days)") | U25: =IF(AND('Master Stock'!D25<>"",'Master Stock'!H25="OCCUPIED",'Master Stock'!J25<>"",'Master Stock'!K25=""),COUNT($U$1:U24)+1,"") | V25: =IF(AND('Master Stock'!D25<>"",'Master Stock'!L25<>"",'Master Stock'!L25<TODAY()-30),COUNT($V$1:V24)+1,"")
A26: {=IFERROR(INDEX('Master Stock'!$D$2:$D$1000,MATCH(5,$U$2:$U$1000,0)),"")} | B26: {=IFERROR(INDEX('Master Stock'!$G$2:$G$1000,MATCH(5,$U$2:$U$1000,0)),"")} | C26: {=IFERROR(INDEX('Master Stock'!$J$2:$J$1000,MATCH(5,$U$2:$U$1000,0)),"")} | D26: =IF(C26="","",MAX(0,TODAY()-C26)) | E26: {=IFERROR(INDEX('Master Stock'!$D$2:$D$1000,MATCH(5,$V$2:$V$1000,0)),"")} | F26: {=IFERROR(INDEX('Master Stock'!$G$2:$G$1000,MATCH(5,$V$2:$V$1000,0)),"")} | G26: {=IFERROR(INDEX('Master Stock'!$L$2:$L$1000,MATCH(5,$V$2:$V$1000,0)),"")} | H26: =IF(G26="","",MAX(0,TODAY()-G26)) | I26: =IF(E26="","","DUE (30+ Days)") | U26: =IF(AND('Master Stock'!D26<>"",'Master Stock'!H26="OCCUPIED",'Master Stock'!J26<>"",'Master Stock'!K26=""),COUNT($U$1:U25)+1,"") | V26: =IF(AND('Master Stock'!D26<>"",'Master Stock'!L26<>"",'Master Stock'!L26<TODAY()-30),COUNT($V$1:V25)+1,"")
A27: {=IFERROR(INDEX('Master Stock'!$D$2:$D$1000,MATCH(6,$U$2:$U$1000,0)),"")} | B27: {=IFERROR(INDEX('Master Stock'!$G$2:$G$1000,MATCH(6,$U$2:$U$1000,0)),"")} | C27: {=IFERROR(INDEX('Master Stock'!$J$2:$J$1000,MATCH(6,$U$2:$U$1000,0)),"")} | D27: =IF(C27="","",MAX(0,TODAY()-C27)) | E27: {=IFERROR(INDEX('Master Stock'!$D$2:$D$1000,MATCH(6,$V$2:$V$1000,0)),"")} | F27: {=IFERROR(INDEX('Master Stock'!$G$2:$G$1000,MATCH(6,$V$2:$V$1000,0)),"")} | G27: {=IFERROR(INDEX('Master Stock'!$L$2:$L$1000,MATCH(6,$V$2:$V$1000,0)),"")} | H27: =IF(G27="","",MAX(0,TODAY()-G27)) | I27: =IF(E27="","","DUE (30+ Days)") | U27: =IF(AND('Master Stock'!D27<>"",'Master Stock'!H27="OCCUPIED",'Master Stock'!J27<>"",'Master Stock'!K27=""),COUNT($U$1:U26)+1,"") | V27: =IF(AND('Master Stock'!D27<>"",'Master Stock'!L27<>"",'Master Stock'!L27<TODAY()-30),COUNT($V$1:V26)+1,"")
A28: {=IFERROR(INDEX('Master Stock'!$D$2:$D$1000,MATCH(7,$U$2:$U$1000,0)),"")} | B28: {=IFERROR(INDEX('Master Stock'!$G$2:$G$1000,MATCH(7,$U$2:$U$1000,0)),"")} | C28: {=IFERROR(INDEX('Master Stock'!$J$2:$J$1000,MATCH(7,$U$2:$U$1000,0)),"")} | D28: =IF(C28="","",MAX(0,TODAY()-C28)) | E28: {=IFERROR(INDEX('Master Stock'!$D$2:$D$1000,MATCH(7,$V$2:$V$1000,0)),"")} | F28: {=IFERROR(INDEX('Master Stock'!$G$2:$G$1000,MATCH(7,$V$2:$V$1000,0)),"")} | G28: {=IFERROR(INDEX('Master Stock'!$L$2:$L$1000,MATCH(7,$V$2:$V$1000,0)),"")} | H28: =IF(G28="","",MAX(0,TODAY()-G28)) | I28: =IF(E28="","","DUE (30+ Days)") | U28: =IF(AND('Master Stock'!D28<>"",'Master Stock'!H28="OCCUPIED",'Master Stock'!J28<>"",'Master Stock'!K28=""),COUNT($U$1:U27)+1,"") | V28: =IF(AND('Master Stock'!D28<>"",'Master Stock'!L28<>"",'Master Stock'!L28<TODAY()-30),COUNT($V$1:V27)+1,"")
A29: {=IFERROR(INDEX('Master Stock'!$D$2:$D$1000,MATCH(8,$U$2:$U$1000,0)),"")} | B29: {=IFERROR(INDEX('Master Stock'!$G$2:$G$1000,MATCH(8,$U$2:$U$1000,0)),"")} | C29: {=IFERROR(INDEX('Master Stock'!$J$2:$J$1000,MATCH(8,$U$2:$U$1000,0)),"")} | D29: =IF(C29="","",MAX(0,TODAY()-C29)) | E29: {=IFERROR(INDEX('Master Stock'!$D$2:$D$1000,MATCH(8,$V$2:$V$1000,0)),"")} | F29: {=IFERROR(INDEX('Master Stock'!$G$2:$G$1000,MATCH(8,$V$2:$V$1000,0)),"")} | G29: {=IFERROR(INDEX('Master Stock'!$L$2:$L$1000,MATCH(8,$V$2:$V$1000,0)),"")} | H29: =IF(G29="","",MAX(0,TODAY()-G29)) | I29: =IF(E29="","","DUE (30+ Days)") | U29: =IF(AND('Master Stock'!D29<>"",'Master Stock'!H29="OCCUPIED",'Master Stock'!J29<>"",'Master Stock'!K29=""),COUNT($U$1:U28)+1,"") | V29: =IF(AND('Master Stock'!D29<>"",'Master Stock'!L29<>"",'Master Stock'!L29<TODAY()-30),COUNT($V$1:V28)+1,"")
A30: {=IFERROR(INDEX('Master Stock'!$D$2:$D$1000,MATCH(9,$U$2:$U$1000,0)),"")} | B30: {=IFERROR(INDEX('Master Stock'!$G$2:$G$1000,MATCH(9,$U$2:$U$1000,0)),"")} | C30: {=IFERROR(INDEX('Master Stock'!$J$2:$J$1000,MATCH(9,$U$2:$U$1000,0)),"")} | D30: =IF(C30="","",MAX(0,TODAY()-C30)) | E30: {=IFERROR(INDEX('Master Stock'!$D$2:$D$1000,MATCH(9,$V$2:$V$1000,0)),"")} | F30: {=IFERROR(INDEX('Master Stock'!$G$2:$G$1000,MATCH(9,$V$2:$V$1000,0)),"")} | G30: {=IFERROR(INDEX('Master Stock'!$L$2:$L$1000,MATCH(9,$V$2:$V$1000,0)),"")} | H30: =IF(G30="","",MAX(0,TODAY()-G30)) | I30: =IF(E30="","","DUE (30+ Days)") | K30: Keep Stack Safe, Keep Quality Safe! | U30: =IF(AND('Master Stock'!D30<>"",'Master Stock'!H30="OCCUPIED",'Master Stock'!J30<>"",'Master Stock'!K30=""),COUNT($U$1:U29)+1,"") | V30: =IF(AND('Master Stock'!D30<>"",'Master Stock'!L30<>"",'Master Stock'!L30<TODAY()-30),COUNT($V$1:V29)+1,"")
A31: {=IFERROR(INDEX('Master Stock'!$D$2:$D$1000,MATCH(10,$U$2:$U$1000,0)),"")} | B31: {=IFERROR(INDEX('Master Stock'!$G$2:$G$1000,MATCH(10,$U$2:$U$1000,0)),"")} | C31: {=IFERROR(INDEX('Master Stock'!$J$2:$J$1000,MATCH(10,$U$2:$U$1000,0)),"")} | D31: =IF(C31="","",MAX(0,TODAY()-C31)) | E31: {=IFERROR(INDEX('Master Stock'!$D$2:$D$1000,MATCH(10,$V$2:$V$1000,0)),"")} | F31: {=IFERROR(INDEX('Master Stock'!$G$2:$G$1000,MATCH(10,$V$2:$V$1000,0)),"")} | G31: {=IFERROR(INDEX('Master Stock'!$L$2:$L$1000,MATCH(10,$V$2:$V$1000,0)),"")} | H31: =IF(G31="","",MAX(0,TODAY()-G31)) | I31: =IF(E31="","","DUE (30+ Days)") | U31: =IF(AND('Master Stock'!D31<>"",'Master Stock'!H31="OCCUPIED",'Master Stock'!J31<>"",'Master Stock'!K31=""),COUNT($U$1:U30)+1,"") | V31: =IF(AND('Master Stock'!D31<>"",'Master Stock'!L31<>"",'Master Stock'!L31<TODAY()-30),COUNT($V$1:V30)+1,"")
A32: {=IFERROR(INDEX('Master Stock'!$D$2:$D$1000,MATCH(11,$U$2:$U$1000,0)),"")} | B32: {=IFERROR(INDEX('Master Stock'!$G$2:$G$1000,MATCH(11,$U$2:$U$1000,0)),"")} | C32: {=IFERROR(INDEX('Master Stock'!$J$2:$J$1000,MATCH(11,$U$2:$U$1000,0)),"")} | D32: =IF(C32="","",MAX(0,TODAY()-C32)) | E32: {=IFERROR(INDEX('Master Stock'!$D$2:$D$1000,MATCH(11,$V$2:$V$1000,0)),"")} | F32: {=IFERROR(INDEX('Master Stock'!$G$2:$G$1000,MATCH(11,$V$2:$V$1000,0)),"")} | G32: {=IFERROR(INDEX('Master Stock'!$L$2:$L$1000,MATCH(11,$V$2:$V$1000,0)),"")} | H32: =IF(G32="","",MAX(0,TODAY()-G32)) | I32: =IF(E32="","","DUE (30+ Days)") | U32: =IF(AND('Master Stock'!D32<>"",'Master Stock'!H32="OCCUPIED",'Master Stock'!J32<>"",'Master Stock'!K32=""),COUNT($U$1:U31)+1,"") | V32: =IF(AND('Master Stock'!D32<>"",'Master Stock'!L32<>"",'Master Stock'!L32<TODAY()-30),COUNT($V$1:V31)+1,"")
A33: {=IFERROR(INDEX('Master Stock'!$D$2:$D$1000,MATCH(12,$U$2:$U$1000,0)),"")} | B33: {=IFERROR(INDEX('Master Stock'!$G$2:$G$1000,MATCH(12,$U$2:$U$1000,0)),"")} | C33: {=IFERROR(INDEX('Master Stock'!$J$2:$J$1000,MATCH(12,$U$2:$U$1000,0)),"")} | D33: =IF(C33="","",MAX(0,TODAY()-C33)) | E33: {=IFERROR(INDEX('Master Stock'!$D$2:$D$1000,MATCH(12,$V$2:$V$1000,0)),"")} | F33: {=IFERROR(INDEX('Master Stock'!$G$2:$G$1000,MATCH(12,$V$2:$V$1000,0)),"")} | G33: {=IFERROR(INDEX('Master Stock'!$L$2:$L$1000,MATCH(12,$V$2:$V$1000,0)),"")} | H33: =IF(G33="","",MAX(0,TODAY()-G33)) | I33: =IF(E33="","","DUE (30+ Days)") | U33: =IF(AND('Master Stock'!D33<>"",'Master Stock'!H33="OCCUPIED",'Master Stock'!J33<>"",'Master Stock'!K33=""),COUNT($U$1:U32)+1,"") | V33: =IF(AND('Master Stock'!D33<>"",'Master Stock'!L33<>"",'Master Stock'!L33<TODAY()-30),COUNT($V$1:V32)+1,"")
A34: {=IFERROR(INDEX('Master Stock'!$D$2:$D$1000,MATCH(13,$U$2:$U$1000,0)),"")} | B34: {=IFERROR(INDEX('Master Stock'!$G$2:$G$1000,MATCH(13,$U$2:$U$1000,0)),"")} | C34: {=IFERROR(INDEX('Master Stock'!$J$2:$J$1000,MATCH(13,$U$2:$U$1000,0)),"")} | D34: =IF(C34="","",MAX(0,TODAY()-C34)) | E34: {=IFERROR(INDEX('Master Stock'!$D$2:$D$1000,MATCH(13,$V$2:$V$1000,0)),"")} | F34: {=IFERROR(INDEX('Master Stock'!$G$2:$G$1000,MATCH(13,$V$2:$V$1000,0)),"")} | G34: {=IFERROR(INDEX('Master Stock'!$L$2:$L$1000,MATCH(13,$V$2:$V$1000,0)),"")} | H34: =IF(G34="","",MAX(0,TODAY()-G34)) | I34: =IF(E34="","","DUE (30+ Days)") | U34: =IF(AND('Master Stock'!D34<>"",'Master Stock'!H34="OCCUPIED",'Master Stock'!J34<>"",'Master Stock'!K34=""),COUNT($U$1:U33)+1,"") | V34: =IF(AND('Master Stock'!D34<>"",'Master Stock'!L34<>"",'Master Stock'!L34<TODAY()-30),COUNT($V$1:V33)+1,"")
A35: {=IFERROR(INDEX('Master Stock'!$D$2:$D$1000,MATCH(14,$U$2:$U$1000,0)),"")} | B35: {=IFERROR(INDEX('Master Stock'!$G$2:$G$1000,MATCH(14,$U$2:$U$1000,0)),"")} | C35: {=IFERROR(INDEX('Master Stock'!$J$2:$J$1000,MATCH(14,$U$2:$U$1000,0)),"")} | D35: =IF(C35="","",MAX(0,TODAY()-C35)) | E35: {=IFERROR(INDEX('Master Stock'!$D$2:$D$1000,MATCH(14,$V$2:$V$1000,0)),"")} | F35: {=IFERROR(INDEX('Master Stock'!$G$2:$G$1000,MATCH(14,$V$2:$V$1000,0)),"")} | G35: {=IFERROR(INDEX('Master Stock'!$L$2:$L$1000,MATCH(14,$V$2:$V$1000,0)),"")} | H35: =IF(G35="","",MAX(0,TODAY()-G35)) | I35: =IF(E35="","","DUE (30+ Days)") | U35: =IF(AND('Master Stock'!D35<>"",'Master Stock'!H35="OCCUPIED",'Master Stock'!J35<>"",'Master Stock'!K35=""),COUNT($U$1:U34)+1,"") | V35: =IF(AND('Master Stock'!D35<>"",'Master Stock'!L35<>"",'Master Stock'!L35<TODAY()-30),COUNT($V$1:V34)+1,"")
A36: {=IFERROR(INDEX('Master Stock'!$D$2:$D$1000,MATCH(15,$U$2:$U$1000,0)),"")} | B36: {=IFERROR(INDEX('Master Stock'!$G$2:$G$1000,MATCH(15,$U$2:$U$1000,0)),"")} | C36: {=IFERROR(INDEX('Master Stock'!$J$2:$J$1000,MATCH(15,$U$2:$U$1000,0)),"")} | D36: =IF(C36="","",MAX(0,TODAY()-C36)) | E36: {=IFERROR(INDEX('Master Stock'!$D$2:$D$1000,MATCH(15,$V$2:$V$1000,0)),"")} | F36: {=IFERROR(INDEX('Master Stock'!$G$2:$G$1000,MATCH(15,$V$2:$V$1000,0)),"")} | G36: {=IFERROR(INDEX('Master Stock'!$L$2:$L$1000,MATCH(15,$V$2:$V$1000,0)),"")} | H36: =IF(G36="","",MAX(0,TODAY()-G36)) | I36: =IF(E36="","","DUE (30+ Days)") | U36: =IF(AND('Master Stock'!D36<>"",'Master Stock'!H36="OCCUPIED",'Master Stock'!J36<>"",'Master Stock'!K36=""),COUNT($U$1:U35)+1,"") | V36: =IF(AND('Master Stock'!D36<>"",'Master Stock'!L36<>"",'Master Stock'!L36<TODAY()-30),COUNT($V$1:V35)+1,"")
A37: {=IFERROR(INDEX('Master Stock'!$D$2:$D$1000,MATCH(16,$U$2:$U$1000,0)),"")} | B37: {=IFERROR(INDEX('Master Stock'!$G$2:$G$1000,MATCH(16,$U$2:$U$1000,0)),"")} | C37: {=IFERROR(INDEX('Master Stock'!$J$2:$J$1000,MATCH(16,$U$2:$U$1000,0)),"")} | D37: =IF(C37="","",MAX(0,TODAY()-C37)) | E37: {=IFERROR(INDEX('Master Stock'!$D$2:$D$1000,MATCH(16,$V$2:$V$1000,0)),"")} | F37: {=IFERROR(INDEX('Master Stock'!$G$2:$G$1000,MATCH(16,$V$2:$V$1000,0)),"")} | G37: {=IFERROR(INDEX('Master Stock'!$L$2:$L$1000,MATCH(16,$V$2:$V$1000,0)),"")} | H37: =IF(G37="","",MAX(0,TODAY()-G37)) | I37: =IF(E37="","","DUE (30+ Days)") | U37: =IF(AND('Master Stock'!D37<>"",'Master Stock'!H37="OCCUPIED",'Master Stock'!J37<>"",'Master Stock'!K37=""),COUNT($U$1:U36)+1,"") | V37: =IF(AND('Master Stock'!D37<>"",'Master Stock'!L37<>"",'Master Stock'!L37<TODAY()-30),COUNT($V$1:V36)+1,"")
A38: {=IFERROR(INDEX('Master Stock'!$D$2:$D$1000,MATCH(17,$U$2:$U$1000,0)),"")} | B38: {=IFERROR(INDEX('Master Stock'!$G$2:$G$1000,MATCH(17,$U$2:$U$1000,0)),"")} | C38: {=IFERROR(INDEX('Master Stock'!$J$2:$J$1000,MATCH(17,$U$2:$U$1000,0)),"")} | D38: =IF(C38="","",MAX(0,TODAY()-C38)) | E38: {=IFERROR(INDEX('Master Stock'!$D$2:$D$1000,MATCH(17,$V$2:$V$1000,0)),"")} | F38: {=IFERROR(INDEX('Master Stock'!$G$2:$G$1000,MATCH(17,$V$2:$V$1000,0)),"")} | G38: {=IFERROR(INDEX('Master Stock'!$L$2:$L$1000,MATCH(17,$V$2:$V$1000,0)),"")} | H38: =IF(G38="","",MAX(0,TODAY()-G38)) | I38: =IF(E38="","","DUE (30+ Days)") | U38: =IF(AND('Master Stock'!D38<>"",'Master Stock'!H38="OCCUPIED",'Master Stock'!J38<>"",'Master Stock'!K38=""),COUNT($U$1:U37)+1,"") | V38: =IF(AND('Master Stock'!D38<>"",'Master Stock'!L38<>"",'Master Stock'!L38<TODAY()-30),COUNT($V$1:V37)+1,"")
A39: {=IFERROR(INDEX('Master Stock'!$D$2:$D$1000,MATCH(18,$U$2:$U$1000,0)),"")} | B39: {=IFERROR(INDEX('Master Stock'!$G$2:$G$1000,MATCH(18,$U$2:$U$1000,0)),"")} | C39: {=IFERROR(INDEX('Master Stock'!$J$2:$J$1000,MATCH(18,$U$2:$U$1000,0)),"")} | D39: =IF(C39="","",MAX(0,TODAY()-C39)) | E39: {=IFERROR(INDEX('Master Stock'!$D$2:$D$1000,MATCH(18,$V$2:$V$1000,0)),"")} | F39: {=IFERROR(INDEX('Master Stock'!$G$2:$G$1000,MATCH(18,$V$2:$V$1000,0)),"")} | G39: {=IFERROR(INDEX('Master Stock'!$L$2:$L$1000,MATCH(18,$V$2:$V$1000,0)),"")} | H39: =IF(G39="","",MAX(0,TODAY()-G39)) | I39: =IF(E39="","","DUE (30+ Days)") | U39: =IF(AND('Master Stock'!D39<>"",'Master Stock'!H39="OCCUPIED",'Master Stock'!J39<>"",'Master Stock'!K39=""),COUNT($U$1:U38)+1,"") | V39: =IF(AND('Master Stock'!D39<>"",'Master Stock'!L39<>"",'Master Stock'!L39<TODAY()-30),COUNT($V$1:V38)+1,"")
A40: {=IFERROR(INDEX('Master Stock'!$D$2:$D$1000,MATCH(19,$U$2:$U$1000,0)),"")} | B40: {=IFERROR(INDEX('Master Stock'!$G$2:$G$1000,MATCH(19,$U$2:$U$1000,0)),"")} | C40: {=IFERROR(INDEX('Master Stock'!$J$2:$J$1000,MATCH(19,$U$2:$U$1000,0)),"")} | D40: =IF(C40="","",MAX(0,TODAY()-C40)) | E40: {=IFERROR(INDEX('Master Stock'!$D$2:$D$1000,MATCH(19,$V$2:$V$1000,0)),"")} | F40: {=IFERROR(INDEX('Master Stock'!$G$2:$G$1000,MATCH(19,$V$2:$V$1000,0)),"")} | G40: {=IFERROR(INDEX('Master Stock'!$L$2:$L$1000,MATCH(19,$V$2:$V$1000,0)),"")} | H40: =IF(G40="","",MAX(0,TODAY()-G40)) | I40: =IF(E40="","","DUE (30+ Days)") | U40: =IF(AND('Master Stock'!D40<>"",'Master Stock'!H40="OCCUPIED",'Master Stock'!J40<>"",'Master Stock'!K40=""),COUNT($U$1:U39)+1,"") | V40: =IF(AND('Master Stock'!D40<>"",'Master Stock'!L40<>"",'Master Stock'!L40<TODAY()-30),COUNT($V$1:V39)+1,"")
...

Sheet Dashboard
A1: GODOWN STOCK & TREATMENT DASHBOARD
A3: TOTAL STACKS | C3: OCCUPIED STACKS | E3: CURRENTLY UNDER COVER | G3: TOTAL DEGASSING DUE | I3: TOTAL EMPTY STACKS
A4: =COUNTA('Master Stock'!$C$2:$C$99) | C4: =COUNTIF('Master Stock'!$H$2:$H$99,"OCCUPIED") | E4: =COUNTIFS('Master Stock'!$H$2:$H$99,"OCCUPIED",'Master Stock'!$J$2:$J$99,"<>",'Master Stock'!$K$2:$K$99,"") | G4: =SUM('Master Stock'!$O$2:$O$99) | L4: ='Shed Summary'!D7
A7: CURRENTLY UNDER COVER – STACK DETAILS | G7: FUMIGATION MORE THAN 5 DAYS – DEGASSING DUE
A8: Shed | B8: Stack No. | C8: Fumigation Date | D8: Days Count | G8: Shed | H8: Stack No. | I8: Fumigation Date | J8: Days Count
A9: {=IFERROR(INDEX('Master Stock'!$C$2:$C$99,MATCH(ROWS($A$9:A9),'Master Stock'!$N$2:$N$99,0)),"")} | B9: {=IFERROR(INDEX('Master Stock'!$D$2:$D$99,MATCH(ROWS($A$9:A9),'Master Stock'!$N$2:$N$99,0)),"")} | C9: {=IF(A9="","",IFERROR(INDEX('Master Stock'!$J$2:$J$99,MATCH(ROWS($A$9:A9),'Master Stock'!$N$2:$N$99,0)),""))} | D9: =IF(C9="","",MAX(0,TODAY()-C9)) | G9: {=IFERROR(INDEX('Master Stock'!$C$2:$C$99,MATCH(ROWS($G$9:G9),'Master Stock'!$P$2:$P$99,0)),"")} | H9: {=IFERROR(INDEX('Master Stock'!$D$2:$D$99,MATCH(ROWS($G$9:G9),'Master Stock'!$P$2:$P$99,0)),"")} | I9: {=IF(G9="","",IFERROR(INDEX('Master Stock'!$J$2:$J$99,MATCH(ROWS($G$9:G9),'Master Stock'!$P$2:$P$99,0)),""))} | J9: =IF(I9="","",MAX(0,TODAY()-I9))
A10: {=IFERROR(INDEX('Master Stock'!$C$2:$C$99,MATCH(ROWS($A$9:A10),'Master Stock'!$N$2:$N$99,0)),"")} | B10: {=IFERROR(INDEX('Master Stock'!$D$2:$D$99,MATCH(ROWS($A$9:A10),'Master Stock'!$N$2:$N$99,0)),"")} | C10: {=IF(A10="","",IFERROR(INDEX('Master Stock'!$J$2:$J$99,MATCH(ROWS($A$9:A10),'Master Stock'!$N$2:$N$99,0)),""))} | D10: =IF(C10="","",MAX(0,TODAY()-C10)) | G10: {=IFERROR(INDEX('Master Stock'!$C$2:$C$99,MATCH(ROWS($G$9:G10),'Master Stock'!$P$2:$P$99,0)),"")} | H10: {=IFERROR(INDEX('Master Stock'!$D$2:$D$99,MATCH(ROWS($G$9:G10),'Master Stock'!$P$2:$P$99,0)),"")} | I10: {=IF(G10="","",IFERROR(INDEX('Master Stock'!$J$2:$J$99,MATCH(ROWS($G$9:G10),'Master Stock'!$P$2:$P$99,0)),""))} | J10: =IF(I10="","",MAX(0,TODAY()-I10))
A11: {=IFERROR(INDEX('Master Stock'!$C$2:$C$99,MATCH(ROWS($A$9:A11),'Master Stock'!$N$2:$N$99,0)),"")} | B11: {=IFERROR(INDEX('Master Stock'!$D$2:$D$99,MATCH(ROWS($A$9:A11),'Master Stock'!$N$2:$N$99,0)),"")} | C11: {=IF(A11="","",IFERROR(INDEX('Master Stock'!$J$2:$J$99,MATCH(ROWS($A$9:A11),'Master Stock'!$N$2:$N$99,0)),""))} | D11: =IF(C11="","",MAX(0,TODAY()-C11)) | G11: {=IFERROR(INDEX('Master Stock'!$C$2:$C$99,MATCH(ROWS($G$9:G11),'Master Stock'!$P$2:$P$99,0)),"")} | H11: {=IFERROR(INDEX('Master Stock'!$D$2:$D$99,MATCH(ROWS($G$9:G11),'Master Stock'!$P$2:$P$99,0)),"")} | I11: {=IF(G11="","",IFERROR(INDEX('Master Stock'!$J$2:$J$99,MATCH(ROWS($G$9:G11),'Master Stock'!$P$2:$P$99,0)),""))} | J11: =IF(I11="","",MAX(0,TODAY()-I11))
A12: {=IFERROR(INDEX('Master Stock'!$C$2:$C$99,MATCH(ROWS($A$9:A12),'Master Stock'!$N$2:$N$99,0)),"")} | B12: {=IFERROR(INDEX('Master Stock'!$D$2:$D$99,MATCH(ROWS($A$9:A12),'Master Stock'!$N$2:$N$99,0)),"")} | C12: {=IF(A12="","",IFERROR(INDEX('Master Stock'!$J$2:$J$99,MATCH(ROWS($A$9:A12),'Master Stock'!$N$2:$N$99,0)),""))} | D12: =IF(C12="","",MAX(0,TODAY()-C12)) | G12: {=IFERROR(INDEX('Master Stock'!$C$2:$C$99,MATCH(ROWS($G$9:G12),'Master Stock'!$P$2:$P$99,0)),"")} | H12: {=IFERROR(INDEX('Master Stock'!$D$2:$D$99,MATCH(ROWS($G$9:G12),'Master Stock'!$P$2:$P$99,0)),"")} | I12: {=IF(G12="","",IFERROR(INDEX('Master Stock'!$J$2:$J$99,MATCH(ROWS($G$9:G12),'Master Stock'!$P$2:$P$99,0)),""))} | J12: =IF(I12="","",MAX(0,TODAY()-I12))
A13: {=IFERROR(INDEX('Master Stock'!$C$2:$C$99,MATCH(ROWS($A$9:A13),'Master Stock'!$N$2:$N$99,0)),"")} | B13: {=IFERROR(INDEX('Master Stock'!$D$2:$D$99,MATCH(ROWS($A$9:A13),'Master Stock'!$N$2:$N$99,0)),"")} | C13: {=IF(A13="","",IFERROR(INDEX('Master Stock'!$J$2:$J$99,MATCH(ROWS($A$9:A13),'Master Stock'!$N$2:$N$99,0)),""))} | D13: =IF(C13="","",MAX(0,TODAY()-C13)) | G13: {=IFERROR(INDEX('Master Stock'!$C$2:$C$99,MATCH(ROWS($G$9:G13),'Master Stock'!$P$2:$P$99,0)),"")} | H13: {=IFERROR(INDEX('Master Stock'!$D$2:$D$99,MATCH(ROWS($G$9:G13),'Master Stock'!$P$2:$P$99,0)),"")} | I13: {=IF(G13="","",IFERROR(INDEX('Master Stock'!$J$2:$J$99,MATCH(ROWS($G$9:G13),'Master Stock'!$P$2:$P$99,0)),""))} | J13: =IF(I13="","",MAX(0,TODAY()-I13))
A14: {=IFERROR(INDEX('Master Stock'!$C$2:$C$99,MATCH(ROWS($A$9:A14),'Master Stock'!$N$2:$N$99,0)),"")} | B14: {=IFERROR(INDEX('Master Stock'!$D$2:$D$99,MATCH(ROWS($A$9:A14),'Master Stock'!$N$2:$N$99,0)),"")} | C14: {=IF(A14="","",IFERROR(INDEX('Master Stock'!$J$2:$J$99,MATCH(ROWS($A$9:A14),'Master Stock'!$N$2:$N$99,0)),""))} | D14: =IF(C14="","",MAX(0,TODAY()-C14)) | G14: {=IFERROR(INDEX('Master Stock'!$C$2:$C$99,MATCH(ROWS($G$9:G14),'Master Stock'!$P$2:$P$99,0)),"")} | H14: {=IFERROR(INDEX('Master Stock'!$D$2:$D$99,MATCH(ROWS($G$9:G14),'Master Stock'!$P$2:$P$99,0)),"")} | I14: {=IF(G14="","",IFERROR(INDEX('Master Stock'!$J$2:$J$99,MATCH(ROWS($G$9:G14),'Master Stock'!$P$2:$P$99,0)),""))} | J14: =IF(I14="","",MAX(0,TODAY()-I14))
A15: {=IFERROR(INDEX('Master Stock'!$C$2:$C$99,MATCH(ROWS($A$9:A15),'Master Stock'!$N$2:$N$99,0)),"")} | B15: {=IFERROR(INDEX('Master Stock'!$D$2:$D$99,MATCH(ROWS($A$9:A15),'Master Stock'!$N$2:$N$99,0)),"")} | C15: {=IF(A15="","",IFERROR(INDEX('Master Stock'!$J$2:$J$99,MATCH(ROWS($A$9:A15),'Master Stock'!$N$2:$N$99,0)),""))} | D15: =IF(C15="","",MAX(0,TODAY()-C15)) | G15: {=IFERROR(INDEX('Master Stock'!$C$2:$C$99,MATCH(ROWS($G$9:G15),'Master Stock'!$P$2:$P$99,0)),"")} | H15: {=IFERROR(INDEX('Master Stock'!$D$2:$D$99,MATCH(ROWS($G$9:G15),'Master Stock'!$P$2:$P$99,0)),"")} | I15: {=IF(G15="","",IFERROR(INDEX('Master Stock'!$J$2:$J$99,MATCH(ROWS($G$9:G15),'Master Stock'!$P$2:$P$99,0)),""))} | J15: =IF(I15="","",MAX(0,TODAY()-I15))
A16: {=IFERROR(INDEX('Master Stock'!$C$2:$C$99,MATCH(ROWS($A$9:A16),'Master Stock'!$N$2:$N$99,0)),"")} | B16: {=IFERROR(INDEX('Master Stock'!$D$2:$D$99,MATCH(ROWS($A$9:A16),'Master Stock'!$N$2:$N$99,0)),"")} | C16: {=IF(A16="","",IFERROR(INDEX('Master Stock'!$J$2:$J$99,MATCH(ROWS($A$9:A16),'Master Stock'!$N$2:$N$99,0)),""))} | D16: =IF(C16="","",MAX(0,TODAY()-C16)) | G16: {=IFERROR(INDEX('Master Stock'!$C$2:$C$99,MATCH(ROWS($G$9:G16),'Master Stock'!$P$2:$P$99,0)),"")} | H16: {=IFERROR(INDEX('Master Stock'!$D$2:$D$99,MATCH(ROWS($G$9:G16),'Master Stock'!$P$2:$P$99,0)),"")} | I16: {=IF(G16="","",IFERROR(INDEX('Master Stock'!$J$2:$J$99,MATCH(ROWS($G$9:G16),'Master Stock'!$P$2:$P$99,0)),""))} | J16: =IF(I16="","",MAX(0,TODAY()-I16))
A17: {=IFERROR(INDEX('Master Stock'!$C$2:$C$99,MATCH(ROWS($A$9:A17),'Master Stock'!$N$2:$N$99,0)),"")} | B17: {=IFERROR(INDEX('Master Stock'!$D$2:$D$99,MATCH(ROWS($A$9:A17),'Master Stock'!$N$2:$N$99,0)),"")} | C17: {=IF(A17="","",IFERROR(INDEX('Master Stock'!$J$2:$J$99,MATCH(ROWS($A$9:A17),'Master Stock'!$N$2:$N$99,0)),""))} | D17: =IF(C17="","",MAX(0,TODAY()-C17)) | G17: {=IFERROR(INDEX('Master Stock'!$C$2:$C$99,MATCH(ROWS($G$9:G17),'Master Stock'!$P$2:$P$99,0)),"")} | H17: {=IFERROR(INDEX('Master Stock'!$D$2:$D$99,MATCH(ROWS($G$9:G17),'Master Stock'!$P$2:$P$99,0)),"")} | I17: {=IF(G17="","",IFERROR(INDEX('Master Stock'!$J$2:$J$99,MATCH(ROWS($G$9:G17),'Master Stock'!$P$2:$P$99,0)),""))} | J17: =IF(I17="","",MAX(0,TODAY()-I17))
A18: {=IFERROR(INDEX('Master Stock'!$C$2:$C$99,MATCH(ROWS($A$9:A18),'Master Stock'!$N$2:$N$99,0)),"")} | B18: {=IFERROR(INDEX('Master Stock'!$D$2:$D$99,MATCH(ROWS($A$9:A18),'Master Stock'!$N$2:$N$99,0)),"")} | C18: {=IF(A18="","",IFERROR(INDEX('Master Stock'!$J$2:$J$99,MATCH(ROWS($A$9:A18),'Master Stock'!$N$2:$N$99,0)),""))} | D18: =IF(C18="","",MAX(0,TODAY()-C18)) | G18: {=IFERROR(INDEX('Master Stock'!$C$2:$C$99,MATCH(ROWS($G$9:G18),'Master Stock'!$P$2:$P$99,0)),"")} | H18: {=IFERROR(INDEX('Master Stock'!$D$2:$D$99,MATCH(ROWS($G$9:G18),'Master Stock'!$P$2:$P$99,0)),"")} | I18: {=IF(G18="","",IFERROR(INDEX('Master Stock'!$J$2:$J$99,MATCH(ROWS($G$9:G18),'Master Stock'!$P$2:$P$99,0)),""))} | J18: =IF(I18="","",MAX(0,TODAY()-I18))
A19: {=IFERROR(INDEX('Master Stock'!$C$2:$C$99,MATCH(ROWS($A$9:A19),'Master Stock'!$N$2:$N$99,0)),"")} | B19: {=IFERROR(INDEX('Master Stock'!$D$2:$D$99,MATCH(ROWS($A$9:A19),'Master Stock'!$N$2:$N$99,0)),"")} | C19: {=IF(A19="","",IFERROR(INDEX('Master Stock'!$J$2:$J$99,MATCH(ROWS($A$9:A19),'Master Stock'!$N$2:$N$99,0)),""))} | D19: =IF(C19="","",MAX(0,TODAY()-C19)) | G19: {=IFERROR(INDEX('Master Stock'!$C$2:$C$99,MATCH(ROWS($G$9:G19),'Master Stock'!$P$2:$P$99,0)),"")} | H19: {=IFERROR(INDEX('Master Stock'!$D$2:$D$99,MATCH(ROWS($G$9:G19),'Master Stock'!$P$2:$P$99,0)),"")} | I19: {=IF(G19="","",IFERROR(INDEX('Master Stock'!$J$2:$J$99,MATCH(ROWS($G$9:G19),'Master Stock'!$P$2:$P$99,0)),""))} | J19: =IF(I19="","",MAX(0,TODAY()-I19))
A20: {=IFERROR(INDEX('Master Stock'!$C$2:$C$99,MATCH(ROWS($A$9:A20),'Master Stock'!$N$2:$N$99,0)),"")} | B20: {=IFERROR(INDEX('Master Stock'!$D$2:$D$99,MATCH(ROWS($A$9:A20),'Master Stock'!$N$2:$N$99,0)),"")} | C20: {=IF(A20="","",IFERROR(INDEX('Master Stock'!$J$2:$J$99,MATCH(ROWS($A$9:A20),'Master Stock'!$N$2:$N$99,0)),""))} | D20: =IF(C20="","",MAX(0,TODAY()-C20)) | G20: {=IFERROR(INDEX('Master Stock'!$C$2:$C$99,MATCH(ROWS($G$9:G20),'Master Stock'!$P$2:$P$99,0)),"")} | H20: {=IFERROR(INDEX('Master Stock'!$D$2:$D$99,MATCH(ROWS($G$9:G20),'Master Stock'!$P$2:$P$99,0)),"")} | I20: {=IF(G20="","",IFERROR(INDEX('Master Stock'!$J$2:$J$99,MATCH(ROWS($G$9:G20),'Master Stock'!$P$2:$P$99,0)),""))} | J20: =IF(I20="","",MAX(0,TODAY()-I20))
... A108: {=IFERROR(INDEX('Master Stock'!$C$2:$C$99,MATCH(ROWS($A$9:A108),'Master Stock'!$N$2:$N$99,0)),"")} | B108: {=IFERROR(INDEX('Master Stock'!$D$2:$D$99,MATCH(ROWS($A$9:A108),'Master Stock'!$N$2:$N$99,0)),"")} | C108: {=IF(A108="","",IFERROR(INDEX('Master Stock'!$J$2:$J$99,MATCH(ROWS($A$9:A108),'Master Stock'!$N$2:$N$99,0)),""))} | D108: =IF(C108="","",MAX(0,TODAY()-C108)) | G108: {=IFERROR(INDEX('Master Stock'!$C$2:$C$99,MATCH(ROWS($G$9:G108),'Master Stock'!$P$2:$P$99,0)),"")} | H108: {=IFERROR(INDEX('Master Stock'!$D$2:$D$99,MATCH(ROWS($G$9:G108),'Master Stock'!$P$2:$P$99,0)),"")} | I108: {=IF(G108="","",IFERROR(INDEX('Master Stock'!$J$2:$J$99,MATCH(ROWS($G$9:G108),'Master Stock'!$P$2:$P$99,0)),""))} | J108: =IF(I108="","",MAX(0,TODAY()-I108))
A1002: Shambhu Dayal Meena TA-II FSD Sabarmati

Sheet Master Stock
B1: Receipt Date | C1: Shed No. | D1: Stack No. | E1: Bags | F1: Qty (MT) | G1: Commodity / Crop Year | H1: Status | I1: Storage Period (Days) | J1: Fumigation Date | K1: Degassing Date | L1: LAST FUMIGATION | M1: UnderCover_Flag | N1: UnderCover_Rank | O1: DegassingDue_Flag | P1: DegassingDue_Rank | Q1: Wheat FIFO Rank | R1: Rice FIFO Rank | S1: DESHBOARD
A2: =IF(D2="","",ROWS($D$2:D2)) | B2: 46122 | C2: 9 | D2: 9A01 | E2: 3501 | F2: 170.75947 | G2: FRK RRA 2024-25 | H2: =IF(AND(E2="",F2="",G2=""),"EMPTY","OCCUPIED") | I2: =IF(B2="","",IF(ISNUMBER(B2),MAX(0,TODAY()-B2),"")) | M2: =IF(AND(H2="OCCUPIED",ISNUMBER(J2),K2=""),1,0) | N2: =IF(M2=1,COUNTIF($M$2:M2,1),"") | O2: =IF(AND(H2="OCCUPIED",ISNUMBER(J2),K2=""),--(TODAY()-J2>5),0) | P2: =IF(O2=1,COUNTIF($O$2:O2,1),"") | Q2: =IF(OR(B2="",G2="",H2<>"OCCUPIED"),"",IF(ISNUMBER(SEARCH("WHEAT",G2)),SUMPRODUCT(--ISNUMBER(SEARCH("WHEAT",$G$2:$G$99)),--($H$2:$H$99="OCCUPIED"),--($B$2:$B$99<>""),--(IFERROR(VALUE(LEFT(RIGHT($G$2:$G$99,7),4)),999)<IFERROR(VALUE(LEFT(RIGHT(G2,7),4)),999)))+SUMPRODUCT(--ISNUMBER(SEARCH("WHEAT",$G$2:$G$99)),--($H$2:$H$99="OCCUPIED"),--($B$2:$B$99<>""),--(IFERROR(VALUE(LEFT(RIGHT($G$2:$G$99,7),4)),999)=IFERROR(VALUE(LEFT(RIGHT(G2,7),4)),999)),--($B$2:$B$99<B2))+SUMPRODUCT(--ISNUMBER(SEARCH("WHEAT",$G$2:$G$99)),--($H$2:$H$99="OCCUPIED"),--($B$2:$B$99<>""),--(IFERROR(VALUE(LEFT(RIGHT($G$2:$G$99,7),4)),999)=IFERROR(VALUE(LEFT(RIGHT(G2,7),4)),999)),--($B$2:$B$99=B2),--(ROW($B$2:$B$99)<=ROW())),"")) | R2: =IF(OR(B2="",G2="",H2<>"OCCUPIED"),"",IF(ISERROR(SEARCH("WHEAT",G2)),SUMPRODUCT(--ISERROR(SEARCH("WHEAT",$G$2:$G$99)),--($H$2:$H$99="OCCUPIED"),--($B$2:$B$99<>""),--(IFERROR(VALUE(LEFT(RIGHT($G$2:$G$99,7),4)),999)<IFERROR(VALUE(LEFT(RIGHT(G2,7),4)),999)))+SUMPRODUCT(--ISERROR(SEARCH("WHEAT",$G$2:$G$99)),--($H$2:$H$99="OCCUPIED"),--($B$2:$B$99<>""),--(IFERROR(VALUE(LEFT(RIGHT($G$2:$G$99,7),4)),999)=IFERROR(VALUE(LEFT(RIGHT(G2,7),4)),999)),--($B$2:$B$99<B2))+SUMPRODUCT(--ISERROR(SEARCH("WHEAT",$G$2:$G$99)),--($H$2:$H$99="OCCUPIED"),--($B$2:$B$99<>""),--(IFERROR(VALUE(LEFT(RIGHT($G$2:$G$99,7),4)),999)=IFERROR(VALUE(LEFT(RIGHT(G2,7),4)),999)),--($B$2:$B$99=B2),--(ROW($B$2:$B$99)<=ROW())),""))
A3: =IF(D3="","",ROWS($D$2:D3)) | B3: 45823 | C3: 9 | D3: 9A02 | E3: 3501 | F3: 173.68484 | G3: WHEAT FAQ 2025-26 | H3: =IF(AND(E3="",F3="",G3=""),"EMPTY","OCCUPIED") | I3: =IF(B3="","",IF(ISNUMBER(B3),MAX(0,TODAY()-B3),"")) | M3: =IF(AND(H3="OCCUPIED",ISNUMBER(J3),K3=""),1,0) | N3: =IF(M3=1,COUNTIF($M$2:M3,1),"") | O3: =IF(AND(H3="OCCUPIED",ISNUMBER(J3),K3=""),--(TODAY()-J3>5),0) | P3: =IF(O3=1,COUNTIF($O$2:O3,1),"") | Q3: =IF(OR(B3="",G3="",H3<>"OCCUPIED"),"",IF(ISNUMBER(SEARCH("WHEAT",G3)),SUMPRODUCT(--ISNUMBER(SEARCH("WHEAT",$G$2:$G$99)),--($H$2:$H$99="OCCUPIED"),--($B$2:$B$99<>""),--(IFERROR(VALUE(LEFT(RIGHT($G$2:$G$99,7),4)),999)<IFERROR(VALUE(LEFT(RIGHT(G3,7),4)),999)))+SUMPRODUCT(--ISNUMBER(SEARCH("WHEAT",$G$2:$G$99)),--($H$2:$H$99="OCCUPIED"),--($B$2:$B$99<>""),--(IFERROR(VALUE(LEFT(RIGHT($G$2:$G$99,7),4)),999)=IFERROR(VALUE(LEFT(RIGHT(G3,7),4)),999)),--($B$2:$B$99<B3))+SUMPRODUCT(--ISNUMBER(SEARCH("WHEAT",$G$2:$G$99)),--($H$2:$H$99="OCCUPIED"),--($B$2:$B$99<>""),--(IFERROR(VALUE(LEFT(RIGHT($G$2:$G$99,7),4)),999)=IFERROR(VALUE(LEFT(RIGHT(G3,7),4)),999)),--($B$2:$B$99=B3),--(ROW($B$2:$B$99)<=ROW())),"")) | R3: =IF(OR(B3="",G3="",H3<>"OCCUPIED"),"",IF(ISERROR(SEARCH("WHEAT",G3)),SUMPRODUCT(--ISERROR(SEARCH("WHEAT",$G$2:$G$99)),--($H$2:$H$99="OCCUPIED"),--($B$2:$B$99<>""),--(IFERROR(VALUE(LEFT(RIGHT($G$2:$G$99,7),4)),999)<IFERROR(VALUE(LEFT(RIGHT(G3,7),4)),999)))+SUMPRODUCT(--ISERROR(SEARCH("WHEAT",$G$2:$G$99)),--($H$2:$H$99="OCCUPIED"),--($B$2:$B$99<>""),--(IFERROR(VALUE(LEFT(RIGHT($G$2:$G$99,7),4)),999)=IFERROR(VALUE(LEFT(RIGHT(G3,7),4)),999)),--($B$2:$B$99<B3))+SUMPRODUCT(--ISERROR(SEARCH("WHEAT",$G$2:$G$99)),--($H$2:$H$99="OCCUPIED"),--($B$2:$B$99<>""),--(IFERROR(VALUE(LEFT(RIGHT($G$2:$G$99,7),4)),999)=IFERROR(VALUE(LEFT(RIGHT(G3,7),4)),999)),--($B$2:$B$99=B3),--(ROW($B$2:$B$99)<=ROW())),""))
A4: =IF(D4="","",ROWS($D$2:D4)) | B4: 45775 | C4: 9 | D4: 9A03 | E4: 3501 | F4: 174.7199 | G4: WHEAT FAQ 2025-26 | H4: =IF(AND(E4="",F4="",G4=""),"EMPTY","OCCUPIED") | I4: =IF(B4="","",IF(ISNUMBER(B4),MAX(0,TODAY()-B4),"")) | M4: =IF(AND(H4="OCCUPIED",ISNUMBER(J4),K4=""),1,0) | N4: =IF(M4=1,COUNTIF($M$2:M4,1),"") | O4: =IF(AND(H4="OCCUPIED",ISNUMBER(J4),K4=""),--(TODAY()-J4>5),0) | P4: =IF(O4=1,COUNTIF($O$2:O4,1),"") | Q4: =IF(OR(B4="",G4="",H4<>"OCCUPIED"),"",IF(ISNUMBER(SEARCH("WHEAT",G4)),SUMPRODUCT(--ISNUMBER(SEARCH("WHEAT",$G$2:$G$99)),--($H$2:$H$99="OCCUPIED"),--($B$2:$B$99<>""),--(IFERROR(VALUE(LEFT(RIGHT($G$2:$G$99,7),4)),999)<IFERROR(VALUE(LEFT(RIGHT(G4,7),4)),999)))+SUMPRODUCT(--ISNUMBER(SEARCH("WHEAT",$G$2:$G$99)),--($H$2:$H$99="OCCUPIED"),--($B$2:$B$99<>""),--(IFERROR(VALUE(LEFT(RIGHT($G$2:$G$99,7),4)),999)=IFERROR(VALUE(LEFT(RIGHT(G4,7),4)),999)),--($B$2:$B$99<B4))+SUMPRODUCT(--ISNUMBER(SEARCH("WHEAT",$G$2:$G$99)),--($H$2:$H$99="OCCUPIED"),--($B$2:$B$99<>""),--(IFERROR(VALUE(LEFT(RIGHT($G$2:$G$99,7),4)),999)=IFERROR(VALUE(LEFT(RIGHT(G4,7),4)),999)),--($B$2:$B$99=B4),--(ROW($B$2:$B$99)<=ROW())),"")) | R4: =IF(OR(B4="",G4="",H4<>"OCCUPIED"),"",IF(ISERROR(SEARCH("WHEAT",G4)),SUMPRODUCT(--ISERROR(SEARCH("WHEAT",$G$2:$G$99)),--($H$2:$H$99="OCCUPIED"),--($B$2:$B$99<>""),--(IFERROR(VALUE(LEFT(RIGHT($G$2:$G$99,7),4)),999)<IFERROR(VALUE(LEFT(RIGHT(G4,7),4)),999)))+SUMPRODUCT(--ISERROR(SEARCH("WHEAT",$G$2:$G$99)),--($H$2:$H$99="OCCUPIED"),--($B$2:$B$99<>""),--(IFERROR(VALUE(LEFT(RIGHT($G$2:$G$99,7),4)),999)=IFERROR(VALUE(LEFT(RIGHT(G4,7),4)),999)),--($B$2:$B$99<B4))+SUMPRODUCT(--ISERROR(SEARCH("WHEAT",$G$2:$G$99)),--($H$2:$H$99="OCCUPIED"),--($B$2:$B$99<>""),--(IFERROR(VALUE(LEFT(RIGHT($G$2:$G$99,7),4)),999)=IFERROR(VALUE(LEFT(RIGHT(G4,7),4)),999)),--($B$2:$B$99=B4),--(ROW($B$2:$B$99)<=ROW())),""))
A5: =IF(D5="","",ROWS($D$2:D5)) | B5: 46220 | C5: 9 | D5: 9A04 | E5: 3413 | F5: 164.83576 | G5: FRK RRA 2023-24 | H5: =IF(AND(E5="",F5="",G5=""),"EMPTY","OCCUPIED") | I5: =IF(B5="","",IF(ISNUMBER(B5),MAX(0,TODAY()-B5),"")) | M5: =IF(AND(H5="OCCUPIED",ISNUMBER(J5),K5=""),1,0) | N5: =IF(M5=1,COUNTIF($M$2:M5,1),"") | O5: =IF(AND(H5="OCCUPIED",ISNUMBER(J5),K5=""),--(TODAY()-J5>5),0) | P5: =IF(O5=1,COUNTIF($O$2:O5,1),"") | Q5: =IF(OR(B5="",G5="",H5<>"OCCUPIED"),"",IF(ISNUMBER(SEARCH("WHEAT",G5)),SUMPRODUCT(--ISNUMBER(SEARCH("WHEAT",$G$2:$G$99)),--($H$2:$H$99="OCCUPIED"),--($B$2:$B$99<>""),--(IFERROR(VALUE(LEFT(RIGHT($G$2:$G$99,7),4)),999)<IFERROR(VALUE(LEFT(RIGHT(G5,7),4)),999)))+SUMPRODUCT(--ISNUMBER(SEARCH("WHEAT",$G$2:$G$99)),--($H$2:$H$99="OCCUPIED"),--($B$2:$B$99<>""),--(IFERROR(VALUE(LEFT(RIGHT($G$2:$G$99,7),4)),999)=IFERROR(VALUE(LEFT(RIGHT(G5,7),4)),999)),--($B$2:$B$99<B5))+SUMPRODUCT(--ISNUMBER(SEARCH("WHEAT",$G$2:$G$99)),--($H$2:$H$99="OCCUPIED"),--($B$2:$B$99<>""),--(IFERROR(VALUE(LEFT(RIGHT($G$2:$G$99,7),4)),999)=IFERROR(VALUE(LEFT(RIGHT(G5,7),4)),999)),--($B$2:$B$99=B5),--(ROW($B$2:$B$99)<=ROW())),"")) | R5: =IF(OR(B5="",G5="",H5<>"OCCUPIED"),"",IF(ISERROR(SEARCH("WHEAT",G5)),SUMPRODUCT(--ISERROR(SEARCH("WHEAT",$G$2:$G$99)),--($H$2:$H$99="OCCUPIED"),--($B$2:$B$99<>""),--(IFERROR(VALUE(LEFT(RIGHT($G$2:$G$99,7),4)),999)<IFERROR(VALUE(LEFT(RIGHT(G5,7),4)),999)))+SUMPRODUCT(--ISERROR(SEARCH("WHEAT",$G$2:$G$99)),--($H$2:$H$99="OCCUPIED"),--($B$2:$B$99<>""),--(IFERROR(VALUE(LEFT(RIGHT($G$2:$G$99,7),4)),999)=IFERROR(VALUE(LEFT(RIGHT(G5,7),4)),999)),--($B$2:$B$99<B5))+SUMPRODUCT(--ISERROR(SEARCH("WHEAT",$G$2:$G$99)),--($H$2:$H$99="OCCUPIED"),--($B$2:$B$99<>""),--(IFERROR(VALUE(LEFT(RIGHT($G$2:$G$99,7),4)),999)=IFERROR(VALUE(LEFT(RIGHT(G5,7),4)),999)),--($B$2:$B$99=B5),--(ROW($B$2:$B$99)<=ROW())),""))
A6: =IF(D6="","",ROWS($D$2:D6)) | B6: 45812 | C6: 9 | D6: 9A05 | E6: 3501 | F6: 174.25028 | G6: WHEAT FAQ 2025-26 | H6: =IF(AND(E6="",F6="",G6=""),"EMPTY","OCCUPIED") | I6: =IF(B6="","",IF(ISNUMBER(B6),MAX(0,TODAY()-B6),"")) | M6: =IF(AND(H6="OCCUPIED",ISNUMBER(J6),K6=""),1,0) | N6: =IF(M6=1,COUNTIF($M$2:M6,1),"") | O6: =IF(AND(H6="OCCUPIED",ISNUMBER(J6),K6=""),--(TODAY()-J6>5),0) | P6: =IF(O6=1,COUNTIF($O$2:O6,1),"") | Q6: =IF(OR(B6="",G6="",H6<>"OCCUPIED"),"",IF(ISNUMBER(SEARCH("WHEAT",G6)),SUMPRODUCT(--ISNUMBER(SEARCH("WHEAT",$G$2:$G$99)),--($H$2:$H$99="OCCUPIED"),--($B$2:$B$99<>""),--(IFERROR(VALUE(LEFT(RIGHT($G$2:$G$99,7),4)),999)<IFERROR(VALUE(LEFT(RIGHT(G6,7),4)),999)))+SUMPRODUCT(--ISNUMBER(SEARCH("WHEAT",$G$2:$G$99)),--($H$2:$H$99="OCCUPIED"),--($B$2:$B$99<>""),--(IFERROR(VALUE(LEFT(RIGHT($G$2:$G$99,7),4)),999)=IFERROR(VALUE(LEFT(RIGHT(G6,7),4)),999)),--($B$2:$B$99<B6))+SUMPRODUCT(--ISNUMBER(SEARCH("WHEAT",$G$2:$G$99)),--($H$2:$H$99="OCCUPIED"),--($B$2:$B$99<>""),--(IFERROR(VALUE(LEFT(RIGHT($G$2:$G$99,7),4)),999)=IFERROR(VALUE(LEFT(RIGHT(G6,7),4)),999)),--($B$2:$B$99=B6),--(ROW($B$2:$B$99)<=ROW())),"")) | R6: =IF(OR(B6="",G6="",H6<>"OCCUPIED"),"",IF(ISERROR(SEARCH("WHEAT",G6)),SUMPRODUCT(--ISERROR(SEARCH("WHEAT",$G$2:$G$99)),--($H$2:$H$99="OCCUPIED"),--($B$2:$B$99<>""),--(IFERROR(VALUE(LEFT(RIGHT($G$2:$G$99,7),4)),999)<IFERROR(VALUE(LEFT(RIGHT(G6,7),4)),999)))+SUMPRODUCT(--ISERROR(SEARCH("WHEAT",$G$2:$G$99)),--($H$2:$H$99="OCCUPIED"),--($B$2:$B$99<>""),--(IFERROR(VALUE(LEFT(RIGHT($G$2:$G$99,7),4)),999)=IFERROR(VALUE(LEFT(RIGHT(G6,7),4)),999)),--($B$2:$B$99<B6))+SUMPRODUCT(--ISERROR(SEARCH("WHEAT",$G$2:$G$99)),--($H$2:$H$99="OCCUPIED"),--($B$2:$B$99<>""),--(IFERROR(VALUE(LEFT(RIGHT($G$2:$G$99,7),4)),999)=IFERROR(VALUE(LEFT(RIGHT(G6,7),4)),999)),--($B$2:$B$99=B6),--(ROW($B$2:$B$99)<=ROW())),""))
A7: =IF(D7="","",ROWS($D$2:D7)) | C7: 9 | D7: 9A06 | H7: =IF(AND(E7="",F7="",G7=""),"EMPTY","OCCUPIED") | I7: =IF(B7="","",IF(ISNUMBER(B7),MAX(0,TODAY()-B7),"")) | M7: =IF(AND(H7="OCCUPIED",ISNUMBER(J7),K7=""),1,0) | N7: =IF(M7=1,COUNTIF($M$2:M7,1),"") | O7: =IF(AND(H7="OCCUPIED",ISNUMBER(J7),K7=""),--(TODAY()-J7>5),0) | P7: =IF(O7=1,COUNTIF($O$2:O7,1),"") | Q7: =IF(OR(B7="",G7="",H7<>"OCCUPIED"),"",IF(ISNUMBER(SEARCH("WHEAT",G7)),SUMPRODUCT(--ISNUMBER(SEARCH("WHEAT",$G$2:$G$99)),--($H$2:$H$99="OCCUPIED"),--($B$2:$B$99<>""),--(IFERROR(VALUE(LEFT(RIGHT($G$2:$G$99,7),4)),999)<IFERROR(VALUE(LEFT(RIGHT(G7,7),4)),999)))+SUMPRODUCT(--ISNUMBER(SEARCH("WHEAT",$G$2:$G$99)),--($H$2:$H$99="OCCUPIED"),--($B$2:$B$99<>""),--(IFERROR(VALUE(LEFT(RIGHT($G$2:$G$99,7),4)),999)=IFERROR(VALUE(LEFT(RIGHT(G7,7),4)),999)),--($B$2:$B$99<B7))+SUMPRODUCT(--ISNUMBER(SEARCH("WHEAT",$G$2:$G$99)),--($H$2:$H$99="OCCUPIED"),--($B$2:$B$99<>""),--(IFERROR(VALUE(LEFT(RIGHT($G$2:$G$99,7),4)),999)=IFERROR(VALUE(LEFT(RIGHT(G7,7),4)),999)),--($B$2:$B$99=B7),--(ROW($B$2:$B$99)<=ROW())),"")) | R7: =IF(OR(B7="",G7="",H7<>"OCCUPIED"),"",IF(ISERROR(SEARCH("WHEAT",G7)),SUMPRODUCT(--ISERROR(SEARCH("WHEAT",$G$2:$G$99)),--($H$2:$H$99="OCCUPIED"),--($B$2:$B$99<>""),--(IFERROR(VALUE(LEFT(RIGHT($G$2:$G$99,7),4)),999)<IFERROR(VALUE(LEFT(RIGHT(G7,7),4)),999)))+SUMPRODUCT(--ISERROR(SEARCH("WHEAT",$G$2:$G$99)),--($H$2:$H$99="OCCUPIED"),--($B$2:$B$99<>""),--(IFERROR(VALUE(LEFT(RIGHT($G$2:$G$99,7),4)),999)=IFERROR(VALUE(LEFT(RIGHT(G7,7),4)),999)),--($B$2:$B$99<B7))+SUMPRODUCT(--ISERROR(SEARCH("WHEAT",$G$2:$G$99)),--($H$2:$H$99="OCCUPIED"),--($B$2:$B$99<>""),--(IFERROR(VALUE(LEFT(RIGHT($G$2:$G$99,7),4)),999)=IFERROR(VALUE(LEFT(RIGHT(G7,7),4)),999)),--($B$2:$B$99=B7),--(ROW($B$2:$B$99)<=ROW())),""))
A8: =IF(D8="","",ROWS($D$2:D8)) | B8: 46108 | C8: 9 | D8: 9A07 | E8: 3501 | F8: 172.96462 | G8: FRK RRA 2024-25 | H8: =IF(AND(E8="",F8="",G8=""),"EMPTY","OCCUPIED") | I8: =IF(B8="","",IF(ISNUMBER(B8),MAX(0,TODAY()-B8),"")) | M8: =IF(AND(H8="OCCUPIED",ISNUMBER(J8),K8=""),1,0) | N8: =IF(M8=1,COUNTIF($M$2:M8,1),"") | O8: =IF(AND(H8="OCCUPIED",ISNUMBER(J8),K8=""),--(TODAY()-J8>5),0) | P8: =IF(O8=1,COUNTIF($O$2:O8,1),"") | Q8: =IF(OR(B8="",G8="",H8<>"OCCUPIED"),"",IF(ISNUMBER(SEARCH("WHEAT",G8)),SUMPRODUCT(--ISNUMBER(SEARCH("WHEAT",$G$2:$G$99)),--($H$2:$H$99="OCCUPIED"),--($B$2:$B$99<>""),--(IFERROR(VALUE(LEFT(RIGHT($G$2:$G$99,7),4)),999)<IFERROR(VALUE(LEFT(RIGHT(G8,7),4)),999)))+SUMPRODUCT(--ISNUMBER(SEARCH("WHEAT",$G$2:$G$99)),--($H$2:$H$99="OCCUPIED"),--($B$2:$B$99<>""),--(IFERROR(VALUE(LEFT(RIGHT($G$2:$G$99,7),4)),999)=IFERROR(VALUE(LEFT(RIGHT(G8,7),4)),999)),--($B$2:$B$99<B8))+SUMPRODUCT(--ISNUMBER(SEARCH("WHEAT",$G$2:$G$99)),--($H$2:$H$99="OCCUPIED"),--($B$2:$B$99<>""),--(IFERROR(VALUE(LEFT(RIGHT($G$2:$G$99,7),4)),999)=IFERROR(VALUE(LEFT(RIGHT(G8,7),4)),999)),--($B$2:$B$99=B8),--(ROW($B$2:$B$99)<=ROW())),"")) | R8: =IF(OR(B8="",G8="",H8<>"OCCUPIED"),"",IF(ISERROR(SEARCH("WHEAT",G8)),SUMPRODUCT(--ISERROR(SEARCH("WHEAT",$G$2:$G$99)),--($H$2:$H$99="OCCUPIED"),--($B$2:$B$99<>""),--(IFERROR(VALUE(LEFT(RIGHT($G$2:$G$99,7),4)),999)<IFERROR(VALUE(LEFT(RIGHT(G8,7),4)),999)))+SUMPRODUCT(--ISERROR(SEARCH("WHEAT",$G$2:$G$99)),--($H$2:$H$99="OCCUPIED"),--($B$2:$B$99<>""),--(IFERROR(VALUE(LEFT(RIGHT($G$2:$G$99,7),4)),999)=IFERROR(VALUE(LEFT(RIGHT(G8,7),4)),999)),--($B$2:$B$99<B8))+SUMPRODUCT(--ISERROR(SEARCH("WHEAT",$G$2:$G$99)),--($H$2:$H$99="OCCUPIED"),--($B$2:$B$99<>""),--(IFERROR(VALUE(LEFT(RIGHT($G$2:$G$99,7),4)),999)=IFERROR(VALUE(LEFT(RIGHT(G8,7),4)),999)),--($B$2:$B$99=B8),--(ROW($B$2:$B$99)<=ROW())),""))
A9: =IF(D9="","",ROWS($D$2:D9)) | B9: 46110 | C9: 9 | D9: 9A08 | E9: 3501 | F9: 173.95336 | G9: FRK RRA 2024-25 | H9: =IF(AND(E9="",F9="",G9=""),"EMPTY","OCCUPIED") | I9: =IF(B9="","",IF(ISNUMBER(B9),MAX(0,TODAY()-B9),"")) | M9: =IF(AND(H9="OCCUPIED",ISNUMBER(J9),K9=""),1,0) | N9: =IF(M9=1,COUNTIF($M$2:M9,1),"") | O9: =IF(AND(H9="OCCUPIED",ISNUMBER(J9),K9=""),--(TODAY()-J9>5),0) | P9: =IF(O9=1,COUNTIF($O$2:O9,1),"") | Q9: =IF(OR(B9="",G9="",H9<>"OCCUPIED"),"",IF(ISNUMBER(SEARCH("WHEAT",G9)),SUMPRODUCT(--ISNUMBER(SEARCH("WHEAT",$G$2:$G$99)),--($H$2:$H$99="OCCUPIED"),--($B$2:$B$99<>""),--(IFERROR(VALUE(LEFT(RIGHT($G$2:$G$99,7),4)),999)<IFERROR(VALUE(LEFT(RIGHT(G9,7),4)),999)))+SUMPRODUCT(--ISNUMBER(SEARCH("WHEAT",$G$2:$G$99)),--($H$2:$H$99="OCCUPIED"),--($B$2:$B$99<>""),--(IFERROR(VALUE(LEFT(RIGHT($G$2:$G$99,7),4)),999)=IFERROR(VALUE(LEFT(RIGHT(G9,7),4)),999)),--($B$2:$B$99<B9))+SUMPRODUCT(--ISNUMBER(SEARCH("WHEAT",$G$2:$G$99)),--($H$2:$H$99="OCCUPIED"),--($B$2:$B$99<>""),--(IFERROR(VALUE(LEFT(RIGHT($G$2:$G$99,7),4)),999)=IFERROR(VALUE(LEFT(RIGHT(G9,7),4)),999)),--($B$2:$B$99=B9),--(ROW($B$2:$B$99)<=ROW())),"")) | R9: =IF(OR(B9="",G9="",H9<>"OCCUPIED"),"",IF(ISERROR(SEARCH("WHEAT",G9)),SUMPRODUCT(--ISERROR(SEARCH("WHEAT",$G$2:$G$99)),--($H$2:$H$99="OCCUPIED"),--($B$2:$B$99<>""),--(IFERROR(VALUE(LEFT(RIGHT($G$2:$G$99,7),4)),999)<IFERROR(VALUE(LEFT(RIGHT(G9,7),4)),999)))+SUMPRODUCT(--ISERROR(SEARCH("WHEAT",$G$2:$G$99)),--($H$2:$H$99="OCCUPIED"),--($B$2:$B$99<>""),--(IFERROR(VALUE(LEFT(RIGHT($G$2:$G$99,7),4)),999)=IFERROR(VALUE(LEFT(RIGHT(G9,7),4)),999)),--($B$2:$B$99<B9))+SUMPRODUCT(--ISERROR(SEARCH("WHEAT",$G$2:$G$99)),--($H$2:$H$99="OCCUPIED"),--($B$2:$B$99<>""),--(IFERROR(VALUE(LEFT(RIGHT($G$2:$G$99,7),4)),999)=IFERROR(VALUE(LEFT(RIGHT(G9,7),4)),999)),--($B$2:$B$99=B9),--(ROW($B$2:$B$99)<=ROW())),""))
A10: =IF(D10="","",ROWS($D$2:D10)) | C10: 9 | D10: 9A09 | H10: =IF(AND(E10="",F10="",G10=""),"EMPTY","OCCUPIED") | I10: =IF(B10="","",IF(ISNUMBER(B10),MAX(0,TODAY()-B10),"")) | M10: =IF(AND(H10="OCCUPIED",ISNUMBER(J10),K10=""),1,0) | N10: =IF(M10=1,COUNTIF($M$2:M10,1),"") | O10: =IF(AND(H10="OCCUPIED",ISNUMBER(J10),K10=""),--(TODAY()-J10>5),0) | P10: =IF(O10=1,COUNTIF($O$2:O10,1),"") | Q10: =IF(OR(B10="",G10="",H10<>"OCCUPIED"),"",IF(ISNUMBER(SEARCH("WHEAT",G10)),SUMPRODUCT(--ISNUMBER(SEARCH("WHEAT",$G$2:$G$99)),--($H$2:$H$99="OCCUPIED"),--($B$2:$B$99<>""),--(IFERROR(VALUE(LEFT(RIGHT($G$2:$G$99,7),4)),999)<IFERROR(VALUE(LEFT(RIGHT(G10,7),4)),999)))+SUMPRODUCT(--ISNUMBER(SEARCH("WHEAT",$G$2:$G$99)),--($H$2:$H$99="OCCUPIED"),--($B$2:$B$99<>""),--(IFERROR(VALUE(LEFT(RIGHT($G$2:$G$99,7),4)),999)=IFERROR(VALUE(LEFT(RIGHT(G10,7),4)),999)),--($B$2:$B$99<B10))+SUMPRODUCT(--ISNUMBER(SEARCH("WHEAT",$G$2:$G$99)),--($H$2:$H$99="OCCUPIED"),--($B$2:$B$99<>""),--(IFERROR(VALUE(LEFT(RIGHT($G$2:$G$99,7),4)),999)=IFERROR(VALUE(LEFT(RIGHT(G10,7),4)),999)),--($B$2:$B$99=B10),--(ROW($B$2:$B$99)<=ROW())),"")) | R10: =IF(OR(B10="",G10="",H10<>"OCCUPIED"),"",IF(ISERROR(SEARCH("WHEAT",G10)),SUMPRODUCT(--ISERROR(SEARCH("WHEAT",$G$2:$G$99)),--($H$2:$H$99="OCCUPIED"),--($B$2:$B$99<>""),--(IFERROR(VALUE(LEFT(RIGHT($G$2:$G$99,7),4)),999)<IFERROR(VALUE(LEFT(RIGHT(G10,7),4)),999)))+SUMPRODUCT(--ISERROR(SEARCH("WHEAT",$G$2:$G$99)),--($H$2:$H$99="OCCUPIED"),--($B$2:$B$99<>""),--(IFERROR(VALUE(LEFT(RIGHT($G$2:$G$99,7),4)),999)=IFERROR(VALUE(LEFT(RIGHT(G10,7),4)),999)),--($B$2:$B$99<B10))+SUMPRODUCT(--ISERROR(SEARCH("WHEAT",$G$2:$G$99)),--($H$2:$H$99="OCCUPIED"),--($B$2:$B$99<>""),--(IFERROR(VALUE(LEFT(RIGHT($G$2:$G$99,7),4)),999)=IFERROR(VALUE(LEFT(RIGHT(G10,7),4)),999)),--($B$2:$B$99=B10),--(ROW($B$2:$B$99)<=ROW())),""))
A11: =IF(D11="","",ROWS($D$2:D11)) | B11: 46112 | C11: 9 | D11: 9B10 | E11: 3501 | F11: 170.64756 | G11: FRK RRA 2024-25 | H11: =IF(AND(E11="",F11="",G11=""),"EMPTY","OCCUPIED") | I11: =IF(B11="","",IF(ISNUMBER(B11),MAX(0,TODAY()-B11),"")) | M11: =IF(AND(H11="OCCUPIED",ISNUMBER(J11),K11=""),1,0) | N11: =IF(M11=1,COUNTIF($M$2:M11,1),"") | O11: =IF(AND(H11="OCCUPIED",ISNUMBER(J11),K11=""),--(TODAY()-J11>5),0) | P11: =IF(O11=1,COUNTIF($O$2:O11,1),"") | Q11: =IF(OR(B11="",G11="",H11<>"OCCUPIED"),"",IF(ISNUMBER(SEARCH("WHEAT",G11)),SUMPRODUCT(--ISNUMBER(SEARCH("WHEAT",$G$2:$G$99)),--($H$2:$H$99="OCCUPIED"),--($B$2:$B$99<>""),--(IFERROR(VALUE(LEFT(RIGHT($G$2:$G$99,7),4)),999)<IFERROR(VALUE(LEFT(RIGHT(G11,7),4)),999)))+SUMPRODUCT(--ISNUMBER(SEARCH("WHEAT",$G$2:$G$99)),--($H$2:$H$99="OCCUPIED"),--($B$2:$B$99<>""),--(IFERROR(VALUE(LEFT(RIGHT($G$2:$G$99,7),4)),999)=IFERROR(VALUE(LEFT(RIGHT(G11,7),4)),999)),--($B$2:$B$99<B11))+SUMPRODUCT(--ISNUMBER(SEARCH("WHEAT",$G$2:$G$99)),--($H$2:$H$99="OCCUPIED"),--($B$2:$B$99<>""),--(IFERROR(VALUE(LEFT(RIGHT($G$2:$G$99,7),4)),999)=IFERROR(VALUE(LEFT(RIGHT(G11,7),4)),999)),--($B$2:$B$99=B11),--(ROW($B$2:$B$99)<=ROW())),"")) | R11: =IF(OR(B11="",G11="",H11<>"OCCUPIED"),"",IF(ISERROR(SEARCH("WHEAT",G11)),SUMPRODUCT(--ISERROR(SEARCH("WHEAT",$G$2:$G$99)),--($H$2:$H$99="OCCUPIED"),--($B$2:$B$99<>""),--(IFERROR(VALUE(LEFT(RIGHT($G$2:$G$99,7),4)),999)<IFERROR(VALUE(LEFT(RIGHT(G11,7),4)),999)))+SUMPRODUCT(--ISERROR(SEARCH("WHEAT",$G$2:$G$99)),--($H$2:$H$99="OCCUPIED"),--($B$2:$B$99<>""),--(IFERROR(VALUE(LEFT(RIGHT($G$2:$G$99,7),4)),999)=IFERROR(VALUE(LEFT(RIGHT(G11,7),4)),999)),--($B$2:$B$99<B11))+SUMPRODUCT(--ISERROR(SEARCH("WHEAT",$G$2:$G$99)),--($H$2:$H$99="OCCUPIED"),--($B$2:$B$99<>""),--(IFERROR(VALUE(LEFT(RIGHT($G$2:$G$99,7),4)),999)=IFERROR(VALUE(LEFT(RIGHT(G11,7),4)),999)),--($B$2:$B$99=B11),--(ROW($B$2:$B$99)<=ROW())),""))
A12: =IF(D12="","",ROWS($D$2:D12)) | B12: 45882 | C12: 9 | D12: 9B11 | E12: 3501 | F12: 177.25977 | G12: WHEAT FAQ 2025-26 | H12: =IF(AND(E12="",F12="",G12=""),"EMPTY","OCCUPIED") | I12: =IF(B12="","",IF(ISNUMBER(B12),MAX(0,TODAY()-B12),"")) | M12: =IF(AND(H12="OCCUPIED",ISNUMBER(J12),K12=""),1,0) | N12: =IF(M12=1,COUNTIF($M$2:M12,1),"") | O12: =IF(AND(H12="OCCUPIED",ISNUMBER(J12),K12=""),--(TODAY()-J12>5),0) | P12: =IF(O12=1,COUNTIF($O$2:O12,1),"") | Q12: =IF(OR(B12="",G12="",H12<>"OCCUPIED"),"",IF(ISNUMBER(SEARCH("WHEAT",G12)),SUMPRODUCT(--ISNUMBER(SEARCH("WHEAT",$G$2:$G$99)),--($H$2:$H$99="OCCUPIED"),--($B$2:$B$99<>""),--(IFERROR(VALUE(LEFT(RIGHT($G$2:$G$99,7),4)),999)<IFERROR(VALUE(LEFT(RIGHT(G12,7),4)),999)))+SUMPRODUCT(--ISNUMBER(SEARCH("WHEAT",$G$2:$G$99)),--($H$2:$H$99="OCCUPIED"),--($B$2:$B$99<>""),--(IFERROR(VALUE(LEFT(RIGHT($G$2:$G$99,7),4)),999)=IFERROR(VALUE(LEFT(RIGHT(G12,7),4)),999)),--($B$2:$B$99<B12))+SUMPRODUCT(--ISNUMBER(SEARCH("WHEAT",$G$2:$G$99)),--($H$2:$H$99="OCCUPIED"),--($B$2:$B$99<>""),--(IFERROR(VALUE(LEFT(RIGHT($G$2:$G$99,7),4)),999)=IFERROR(VALUE(LEFT(RIGHT(G12,7),4)),999)),--($B$2:$B$99=B12),--(ROW($B$2:$B$99)<=ROW())),"")) | R12: =IF(OR(B12="",G12="",H12<>"OCCUPIED"),"",IF(ISERROR(SEARCH("WHEAT",G12)),SUMPRODUCT(--ISERROR(SEARCH("WHEAT",$G$2:$G$99)),--($H$2:$H$99="OCCUPIED"),--($B$2:$B$99<>""),--(IFERROR(VALUE(LEFT(RIGHT($G$2:$G$99,7),4)),999)<IFERROR(VALUE(LEFT(RIGHT(G12,7),4)),999)))+SUMPRODUCT(--ISERROR(SEARCH("WHEAT",$G$2:$G$99)),--($H$2:$H$99="OCCUPIED"),--($B$2:$B$99<>""),--(IFERROR(VALUE(LEFT(RIGHT($G$2:$G$99,7),4)),999)=IFERROR(VALUE(LEFT(RIGHT(G12,7),4)),999)),--($B$2:$B$99<B12))+SUMPRODUCT(--ISERROR(SEARCH("WHEAT",$G$2:$G$99)),--($H$2:$H$99="OCCUPIED"),--($B$2:$B$99<>""),--(IFERROR(VALUE(LEFT(RIGHT($G$2:$G$99,7),4)),999)=IFERROR(VALUE(LEFT(RIGHT(G12,7),4)),999)),--($B$2:$B$99=B12),--(ROW($B$2:$B$99)<=ROW())),""))
A13: =IF(D13="","",ROWS($D$2:D13)) | B13: 46108 | C13: 9 | D13: 9B12 | E13: 3501 | F13: 172.85983 | G13: FRK RRA 2024-25 | H13: =IF(AND(E13="",F13="",G13=""),"EMPTY","OCCUPIED") | I13: =IF(B13="","",IF(ISNUMBER(B13),MAX(0,TODAY()-B13),"")) | M13: =IF(AND(H13="OCCUPIED",ISNUMBER(J13),K13=""),1,0) | N13: =IF(M13=1,COUNTIF($M$2:M13,1),"") | O13: =IF(AND(H13="OCCUPIED",ISNUMBER(J13),K13=""),--(TODAY()-J13>5),0) | P13: =IF(O13=1,COUNTIF($O$2:O13,1),"") | Q13: =IF(OR(B13="",G13="",H13<>"OCCUPIED"),"",IF(ISNUMBER(SEARCH("WHEAT",G13)),SUMPRODUCT(--ISNUMBER(SEARCH("WHEAT",$G$2:$G$99)),--($H$2:$H$99="OCCUPIED"),--($B$2:$B$99<>""),--(IFERROR(VALUE(LEFT(RIGHT($G$2:$G$99,7),4)),999)<IFERROR(VALUE(LEFT(RIGHT(G13,7),4)),999)))+SUMPRODUCT(--ISNUMBER(SEARCH("WHEAT",$G$2:$G$99)),--($H$2:$H$99="OCCUPIED"),--($B$2:$B$99<>""),--(IFERROR(VALUE(LEFT(RIGHT($G$2:$G$99,7),4)),999)=IFERROR(VALUE(LEFT(RIGHT(G13,7),4)),999)),--($B$2:$B$99<B13))+SUMPRODUCT(--ISNUMBER(SEARCH("WHEAT",$G$2:$G$99)),--($H$2:$H$99="OCCUPIED"),--($B$2:$B$99<>""),--(IFERROR(VALUE(LEFT(RIGHT($G$2:$G$99,7),4)),999)=IFERROR(VALUE(LEFT(RIGHT(G13,7),4)),999)),--($B$2:$B$99=B13),--(ROW($B$2:$B$99)<=ROW())),"")) | R13: =IF(OR(B13="",G13="",H13<>"OCCUPIED"),"",IF(ISERROR(SEARCH("WHEAT",G13)),SUMPRODUCT(--ISERROR(SEARCH("WHEAT",$G$2:$G$99)),--($H$2:$H$99="OCCUPIED"),--($B$2:$B$99<>""),--(IFERROR(VALUE(LEFT(RIGHT($G$2:$G$99,7),4)),999)<IFERROR(VALUE(LEFT(RIGHT(G13,7),4)),999)))+SUMPRODUCT(--ISERROR(SEARCH("WHEAT",$G$2:$G$99)),--($H$2:$H$99="OCCUPIED"),--($B$2:$B$99<>""),--(IFERROR(VALUE(LEFT(RIGHT($G$2:$G$99,7),4)),999)=IFERROR(VALUE(LEFT(RIGHT(G13,7),4)),999)),--($B$2:$B$99<B13))+SUMPRODUCT(--ISERROR(SEARCH("WHEAT",$G$2:$G$99)),--($H$2:$H$99="OCCUPIED"),--($B$2:$B$99<>""),--(IFERROR(VALUE(LEFT(RIGHT($G$2:$G$99,7),4)),999)=IFERROR(VALUE(LEFT(RIGHT(G13,7),4)),999)),--($B$2:$B$99=B13),--(ROW($B$2:$B$99)<=ROW())),""))
A14: =IF(D14="","",ROWS($D$2:D14)) | B14: 46064 | C14: 9 | D14: 9B13 | E14: 3501 | F14: 172.48073 | G14: FRK RRA 2024-25 | H14: =IF(AND(E14="",F14="",G14=""),"EMPTY","OCCUPIED") | I14: =IF(B14="","",IF(ISNUMBER(B14),MAX(0,TODAY()-B14),"")) | M14: =IF(AND(H14="OCCUPIED",ISNUMBER(J14),K14=""),1,0) | N14: =IF(M14=1,COUNTIF($M$2:M14,1),"") | O14: =IF(AND(H14="OCCUPIED",ISNUMBER(J14),K14=""),--(TODAY()-J14>5),0) | P14: =IF(O14=1,COUNTIF($O$2:O14,1),"") | Q14: =IF(OR(B14="",G14="",H14<>"OCCUPIED"),"",IF(ISNUMBER(SEARCH("WHEAT",G14)),SUMPRODUCT(--ISNUMBER(SEARCH("WHEAT",$G$2:$G$99)),--($H$2:$H$99="OCCUPIED"),--($B$2:$B$99<>""),--(IFERROR(VALUE(LEFT(RIGHT($G$2:$G$99,7),4)),999)<IFERROR(VALUE(LEFT(RIGHT(G14,7),4)),999)))+SUMPRODUCT(--ISNUMBER(SEARCH("WHEAT",$G$2:$G$99)),--($H$2:$H$99="OCCUPIED"),--($B$2:$B$99<>""),--(IFERROR(VALUE(LEFT(RIGHT($G$2:$G$99,7),4)),999)=IFERROR(VALUE(LEFT(RIGHT(G14,7),4)),999)),--($B$2:$B$99<B14))+SUMPRODUCT(--ISNUMBER(SEARCH("WHEAT",$G$2:$G$99)),--($H$2:$H$99="OCCUPIED"),--($B$2:$B$99<>""),--(IFERROR(VALUE(LEFT(RIGHT($G$2:$G$99,7),4)),999)=IFERROR(VALUE(LEFT(RIGHT(G14,7),4)),999)),--($B$2:$B$99=B14),--(ROW($B$2:$B$99)<=ROW())),"")) | R14: =IF(OR(B14="",G14="",H14<>"OCCUPIED"),"",IF(ISERROR(SEARCH("WHEAT",G14)),SUMPRODUCT(--ISERROR(SEARCH("WHEAT",$G$2:$G$99)),--($H$2:$H$99="OCCUPIED"),--($B$2:$B$99<>""),--(IFERROR(VALUE(LEFT(RIGHT($G$2:$G$99,7),4)),999)<IFERROR(VALUE(LEFT(RIGHT(G14,7),4)),999)))+SUMPRODUCT(--ISERROR(SEARCH("WHEAT",$G$2:$G$99)),--($H$2:$H$99="OCCUPIED"),--($B$2:$B$99<>""),--(IFERROR(VALUE(LEFT(RIGHT($G$2:$G$99,7),4)),999)=IFERROR(VALUE(LEFT(RIGHT(G14,7),4)),999)),--($B$2:$B$99<B14))+SUMPRODUCT(--ISERROR(SEARCH("WHEAT",$G$2:$G$99)),--($H$2:$H$99="OCCUPIED"),--($B$2:$B$99<>""),--(IFERROR(VALUE(LEFT(RIGHT($G$2:$G$99,7),4)),999)=IFERROR(VALUE(LEFT(RIGHT(G14,7),4)),999)),--($B$2:$B$99=B14),--(ROW($B$2:$B$99)<=ROW())),""))
